Workbook

Sheet Summary
A1: AI Calculator cost model: headline numbers
A2: All values are formulas pointing at the other sheets. Edit blue cells on 'Inputs', 'Unit cost' and 'Cash budget'.
B4: 5 testers | C4: 10 units | D4: 100 units | E4: 1,000 units
A5: Cost per unit (parts, freight, scrap, batch one-time) | B5: ='Unit cost'!$C$37 | C5: ='Unit cost'!$D$37 | D5: ='Unit cost'!$E$37 | E5: ='Unit cost'!$F$37
A6: Cost per unit incl. FCC / lawyer / LLC / trademark / insurance | B6: ='Unit cost'!$C$40 | C6: ='Unit cost'!$D$40 | D6: ='Unit cost'!$E$40 | E6: ='Unit cost'!$F$40
A7: Hardware profit per $225 unit | B7: ='Margins & payback'!B13 | C7: ='Margins & payback'!C13 | D7: ='Margins & payback'!D13 | E7: ='Margins & payback'!E13
A8: Hardware margin % | B8: ='Margins & payback'!B14 | C8: ='Margins & payback'!C14 | D8: ='Margins & payback'!D14 | E8: ='Margins & payback'!E14
A9: Subscription profit per paying user per month | B9: ='Margins & payback'!B20 | C9: ='Margins & payback'!C20 | D9: ='Margins & payback'!D20 | E9: ='Margins & payback'!E20
A10: Subscription margin % | B10: ='Margins & payback'!B21 | C10: ='Margins & payback'!C21 | D10: ='Margins & payback'!D21 | E10: ='Margins & payback'!E21
A11: Total profit per calculator (hardware + 12 months' subscription) | B11: ='Margins & payback'!B27 | C11: ='Margins & payback'!C27 | D11: ='Margins & payback'!D27 | E11: ='Margins & payback'!E27
A12: Units to cover this batch's one-time costs | B12: ='Margins & payback'!B32 | C12: ='Margins & payback'!C32 | D12: ='Margins & payback'!D32 | E12: ='Margins & payback'!E32
A14: Versions (10 / 100 / 1,000 only; the 5 testers are e-paper)
A15: LCD version: cost per unit incl. selling-legally | B15: n/a | C15: ='Versions'!$C$31 | D15: ='Versions'!$D$31 | E15: ='Versions'!$E$31
A16: LCD version: hardware profit per $225 unit | B16: n/a | C16: ='Versions'!$C$36 | D16: ='Versions'!$D$36 | E16: ='Versions'!$E$36
A17: E-paper + 1,200-1,500 mAh: cost per unit incl. selling-legally | B17: n/a | C17: ='Versions'!$C$32 | D17: ='Versions'!$D$32 | E17: ='Versions'!$E$32
A18: LCD + 1,200-1,500 mAh: cost per unit incl. selling-legally | B18: n/a | C18: ='Versions'!$C$33 | D18: ='Versions'!$D$33 | E18: ='Versions'!$E$33
A19: LCD + 1,200-1,500 mAh: hardware profit per $225 unit | B19: n/a | C19: ='Versions'!$C$38 | D19: ='Versions'!$D$38 | E19: ='Versions'!$E$38
A21: Claude API
A22: Model | B22: ='Inputs'!$B$20
A23: Cost per solve | B23: ='API cost'!$B$15
A24: API cost per subscriber per month (typical use) | B24: ='API cost'!$B$17
A25: API cost per month for a user at the 500 cap | B25: ='API cost'!$B$18
A26: Solves per day that $15 pays for (break-even) | B26: ='API cost'!$B$20
A27: Suggested fair-use cap (solves/month) for break-even | B27: ='API cost'!$B$21
A28: Same API cost per month on Sonnet 5.5 (typical) | B28: ='API cost'!D31
A29: Same on Sonnet 5.5 for a user at the 500 cap | B29: ='API cost'!F31
A31: The $2,000
A32: Planned spend (5 testers → v15 order + panels → v15-LCD pilot) | B32: ='Cash budget'!$D$19
A33: Left over | B33: ='Cash budget'!$D$21
A34: Cash needed before the first 100 public units | B34: ='Cash budget'!$D$26
A35: Pre-orders at $225 that would fund it | B35: ='Cash budget'!$D$27

Sheet Update 2026-10-11
A1: Update 2026-10-11: Proofline prices, v15 ordered (details not recorded), 5 samples then bulk
A2: Facts from Nirav 2026-10-11. Blue = input. Older sheets are kept as history; where they disagree, this sheet wins. v14 was never ordered. v15 order total/vendor/qty/date NOT RECORDED: B19 is the old estimate.
A4: INPUTS
A5: Device price | B5: 225 | E5: Nirav 2026-10-11
A6: Plan, monthly | B6: 10 | E6: $/month
A7: Plan, yearly | B7: 100 | E7: $/year (2 months free)
A8: AI spend cap per account per month | B8: 5 | E8: $
A9: Solve cap per account per month | B9: 300 | E9: solves
A10: AI cost per solve | B10: 0.026 | E10: LAUNCH_ROADMAP.md 3.3, Sonnet 5.5 row (estimate)
A11: Typical solves per user per month | B11: 150 | E11: LAUNCH_ROADMAP.md 3.3 typical (estimate)
A12: Stripe percent | B12: 0.029 | E12: Inputs sheet
A13: Stripe fixed per charge | B13: 0.3 | E13: Inputs sheet
A14: Stripe Billing percent (subscriptions) | B14: 0.007 | E14: Nirav 2026-10-11
A15: Cloudflare Workers per month | B15: 5 | E15: when needed
A16: Conversion after the free month | B16: 0.7 | E16: Inputs sheet (guess)
... A20: Selling-legally one-time | B20: 3547 | E20: FCC + lawyer + LLC + TM + insurance
A21: Budget | B21: 2000
A23: SUBSCRIPTION (per paying user per month)
A24: Monthly plan net | B24: =B6-(B6*(B12+B14)+B13) | E24: ≈ 9.34
A25: Yearly plan net per month | B25: =(B7-(B7*(B12+B14)+B13))/12 | E25: ≈ 8.01
A26: AI typical per month | B26: =MIN(B10*B11,B8) | E26: ≈ 3.90
A27: Solves until the $ cap | B27: =B8/B10 | E27: ≈ 192: the $5 cap binds before 300 solves
A28: Left, 30 % yearly | B28: =0.7*B24+0.3*B25-B26 | E28: ≈ 5.04
A29: Left, 50 % yearly | B29: =0.5*B24+0.5*B25-B26 | E29: ≈ 4.77
A30: Left, 70 % yearly | B30: =0.3*B24+0.7*B25-B26 | E30: ≈ 4.51
A31: Left at the cap, 50 % yearly | B31: =0.5*B24+0.5*B25-B8 | E31: ≈ 3.67
A32: Monthly payer paid months in months 2-12 | B32: =(1-(1-B17)^11)/B17 | E32: ≈ 7.50
A33: Monthly payer 12-month value | B33: =B32*(B24-B26) | E33: ≈ 40.82
A34: Yearly payer 12-month value | B34: =(B7-(B7*(B12+B14)+B13))-12*B26 | E34: ≈ 49.30
A35: 12-month value per device sold, 50 % yearly | B35: =B16*(0.5*B34+0.5*B33) | E35: ≈ 31.54
A37: HARDWARE (per $225 unit, LCD v15)
A38: Before unit cost: price - card fee - shipping - 3 % warranty - free-month AI | B38: =B5-(B5*B12+B13)-6-0.03*B5-B26 | E38: ≈ 201.52 (shipping $6, warranty 3 % from Inputs)
A39: Contribution @100 before selling-legally | B39: =B38-B18 | E39: ≈ 159.30
A40: Break-even units: selling-legally | B40: =ROUNDUP(B20/B39,0) | E40: ≈ 23
A41: Break-even units: + budget + 12 months Cloudflare | B41: =ROUNDUP((B20+B21+12*B15)/B39,0) | E41: ≈ 36
A42: Same with 12-month subscription | B42: =ROUNDUP((B20+B21+12*B15)/(B39+B35),0) | E42: ≈ 30
A44: CASH vs $2,000
A45: v15 order (estimate) | B45: =B19
A46: Parts for 5 v15 samples = 5 x (91.92 - 18.00 board) | B46: 369.6 | E46: Versions LCD @10 minus board
A47: Knockoff shell samples | B47: 60
...

Sheet Inputs
A1: Inputs: every blue number is an assumption you can edit. Black = formula.
A2: Written 2026-10-06, updated 2026-10-08 evening (5 v14 testers, v15-LCD verified ORDER with the BuyDisplay ER-TFT019-1 panel, bigger battery). Sources beside each input. (estimate) = no hard source; confirm by quote.
A4: Input | B4: Value | C4: Unit | D4: Source / why
A5: Pricing and fees
A6: Calculator price | B6: 225 | C6: $ | D6: Decided 2026-10-04 (LAUNCH_ROADMAP.md §0).
A7: Subscription price per month | B7: 15 | C7: $/month | D7: Decided 2026-10-04 (LAUNCH_ROADMAP.md §0).
A8: Free months at the start | B8: 1 | C8: months | D8: First month free = proxy TRIAL_DAYS=30 (server/proxy/config.py).
A9: Fair-use cap, solves per month | B9: 500 | C9: solves | D9: Proxy MONTHLY_CAP=500 (server/proxy/config.py).
A10: Card fee, percent | B10: 0.029 | C10: % | D10: Stripe US standard online card rate 2.9 % + 30¢ (estimate; check your Stripe dashboard).
A11: Card fee, fixed per charge | B11: 0.3 | C11: $ | D11: Stripe US standard 30¢ per charge (estimate).
A12: Shipping one calculator to a customer | B12: 6 | C12: $ | D12: USPS Ground Advantage, ~8 oz padded box, zone 4-5 (estimate).
A13: Returns / warranty allowance (% of price) | B13: 0.03 | C13: % | D13: Roadmap §5: budget 2-5 % of units needing help or replacement (estimate).
A14: Subscription behaviour
A15: Buyers who start paying after the free month | B15: 0.7 | C15: % | D15: Assumption (estimate). Nothing measured yet: replace with beta data.
A16: Monthly cancellation rate of paying users | B16: 0.08 | C16: %/month | D16: Assumption (estimate). Student products churn in summer; 8 %/month ≈ half gone after 8 months.
A17: Months counted for subscription value (LTV) | B17: 12 | C17: months | D17: One school year plus summer. Conservative; anything after month 12 is upside.
A18: Proxy hosting per month (server + database) | B18: 25 | C18: $/month | D18: Small Render/Fly instance + disk (estimate). server/proxy/README.md: not deployed yet.
A19: Claude API usage (per solve)
A20: Model used for solves | B20: Opus 5.5 | D20: Pick from the table below (Opus 5.5 / Sonnet 5.5 / Haiku 4.5). NOTE: the proxy's default MAIN_MODEL today is claude-sonnet-5-5 (config.py).
A21: Solves per active user per day (typical) | B21: 5 | C21: solves/day | D21: Roadmap §3.3 'typical' = 150 solves/month ≈ 5/day (estimate).
A22: Days per month | B22: 30.4 | C22: days | D22: 365 / 12.
A23: Input tokens per solve (photo + prompt) | B23: 2500 | C23: tokens | D23: Roadmap §3.3: photo ≈ (w×h)/750 ≈ 1,600 for 1280×960, plus system prompt ≈ 2,500 total (estimate).
A24: …of which a fixed system prompt that can be cached | B24: 900 | C24: tokens | D24: Estimate. If the fixed prompt is shorter than the model's minimum cacheable prefix (512-4,096 tokens) it will not cache: set 0.
A25: Cache hit rate on that prefix | B25: 0.8 | C25: % | D25: Estimate (cache lives ~5 min; busy hours hit, quiet hours miss).
A26: Cache write price as a multiple of input price | B26: 1.25 | C26: × | D26: Anthropic 5-minute cache write = 1.25× base input.
A27: Batch discount applied | B27: 0 | C27: % | D27: Batch API is 50 % off but answers take minutes to hours: unusable for live solves. Keep 0 %.
A28: Selling legally (one-time, before public sales)
A29: FCC Part 15B SDoC test (1 lab day) | B29: 1750 | C29: $ | D29: Roadmap §4: $1,000-2,500 [S10]; midpoint.
A30: Lawyer: trade dress + terms of service | B30: 300 | C30: $ | D30: Roadmap §4: clinic $0-300; KNOCKOFF_SHELL_PLAN.md §5: private consult $200-500.
A31: Indiana LLC | B31: 97 | C31: $ | D31: Roadmap §4 [S25].
A32: USPTO trademark, classes 9 + 42 | B32: 700 | C32: $ | D32: Roadmap §4: $350 per class [S24].
A33: Product liability insurance, first year | B33: 700 | C33: $ | D33: Roadmap §4: ~$400-1,000/yr (estimate).
A34: JLCPCB assembly fee check (already inside the PCBA price row)
A35: Standard PCBA setup fee per order | B35: 25 | C35: $ | D35: Given 2026-10-06 (JLCPCB Standard PCBA).
A36: Extended-part loading fee per part type | B36: 3 | C36: $ | D36: Roadmap §3.1: $3 × 14 extended types per order (JLCPCB rule).
A37: Extended part types on the board | B37: 14 | C37: types | D37: Roadmap §3.1.
A38: Solder joints per board | B38: 310 | C38: joints | D38: Estimate from the 77-designator BOM: ESP32 module 65, TCA8418 25, 2 FPCs 52, SOT-23s ~45, connectors ~12, ~55 passives × 2.
A39: Price per solder joint at 100 boards | B39: 0.0013 | C39: $ | D39: Given 2026-10-06 (JLCPCB).
A40: Your own time (shown, not added to cost at 2-100)
A41: Your minutes per unit: grind + assemble + QA | B41: 37 | C41: min | D41: Grinds with jigs 9-11 min (jigs/README.md), assembly ~15 min (estimate), QA Part A 5 + Part B 6-8 min (QA_TEST_PLAN.md).
...

Sheet Unit cost
A1: Cost per finished calculator at 5 / 10 / 100 / 1,000 units (e-paper version; LCD and big battery on 'Versions')
A2: 5 = the v14 e-paper TESTERS in genuine Casio fx-115ES shells (option C of Claude outputs/AI_Calculator_Shopping_List.xlsx). 10 / 100 / 1,000 = knockoff 991ES-style shell (v15 board). Per-unit prices from Claude outputs/Alibaba_Bulk_Sourcing.xlsx 'Cost by batch' and LAUNCH_ROADMAP.md §3 unless noted.
A4: # | B4: Item | C4: 5 testers | D4: 10 units | E4: 100 units | F4: 1,000 units | G4: Source / notes
B5: Batch size (units) | C5: 5 | D5: 10 | E5: 100 | F5: 1000 | G5: Edit to test other batch sizes; the per-unit prices below don't re-scale by themselves.
B6: Shell used | C6: Casio donor | D6: Clone (retail) | E6: Clone (Alibaba) | F6: Clone (factory)
A7: Per-unit parts (price per unit at that volume)
A8: 1 | B8: PCB + PCBA (board, all SMD parts, JLCPCB assembly) | C8: 55 | D8: 18 | E8: 9 | F8: 7.3 | G8: 5: JLCPCB v14 DELIVERED (incl. DHL + ~35 % duty) ≈ $220 for 2 assembled + $55 for 5 assembled = $275 ÷ 5 (Shopping List rows 1-2). 10/100/1,000: roadmap §3 table [S8].
A9: 2 | B9: Shell + key mat + window + screws | C9: 20 | D9: 6 | E9: 3.99 | F9: 3.25 | G9: 5: Casio fx-115ES $20 each (3 bought, 2 already owned; value shown for all 5). 10: retail clone incl. shipping. 100: Alibaba $3.25-3.99 MOQ 20 [S1]. 1,000: $3.25 (factories quote $1.50-3.50 at 3,000 [S2]).
A10: 3 | B10: Camera OV5640 AF | C10: 10.594 | D10: 12 | E10: 6 | F10: 4.5 | G10: 5: option C = (3 × Seeed 114993115 $12.99 + 2 × generic $7) ÷ 5. Then roadmap / Alibaba OEM [S3].
A11: 4 | B11: E-paper 2.13" raw panel | C11: 5.994 | D11: 6.6 | E11: 5.5 | F11: 4 | G11: 5: option C = (3 × Waveshare $6.99 + 2 × GDEY0213B74 $4.50) ÷ 5. Then Good Display direct by RFQ (estimate).
A12: 5 | B12: LiPo 150 mAh + JST-PH | C12: 4.77 | D12: 5.95 | E12: 1.8 | F12: 1.3 | G12: 5: option C = (3 × Adafruit #1317 $5.95 + 2 × generic 302030 $3) ÷ 5. 10: Adafruit #1317. 100/1,000: Alibaba cell with PH lead + PCM (estimate).
A13: 6 | B13: Battery dangerous-goods freight surcharge | C13: 0 | D13: 0 | E13: 0.8 | F13: 0.3 | G13: UN3481 air surcharge (estimate).
A14: 7 | B14: Magnetic connector pair | C14: 6.5 | D14: 5.85 | E14: 1.8 | F14: 1.2 | G14: Adafruit #5358 $6.50 / $5.85 (10+); Alibaba MG04-254-RA $1.80 [S7].
A15: 8 | B15: Magnetic USB cable (in the box) | C15: 4.95 | D15: 4.95 | E15: 1.8 | F15: 1.4 | G15: Adafruit #5412 $4.95; OEM $1.40-1.80 (estimate).
A16: 9 | B16: Retail box + insert | C16: 0 | D16: 1.5 | E16: 1 | F16: 0.6 | G16: Prototypes unboxed. Alibaba rigid box $0.20-1.02 @100 [S9].
A17: 10 | B17: Quick-start card (with 'not affiliated with Casio') | C17: 0 | D17: 0.1 | E17: 0.25 | F17: 0.05 | G17: [S10]; small runs estimate.
A18: 11 | B18: Serial / QC label + polybag | C18: 0 | D18: 0.15 | E18: 0.1 | F18: 0.05 | G18: Estimate.
A19: 12 | B19: Tape, Kapton, glue (per-unit share) | C19: 0 | D19: 0.5 | E19: 0.3 | F19: 0.2 | G19: 2: bought as bench tools (one-time row below). Estimate.
A20: 13 | B20: Inbound freight + US import duty (per unit) | C20: 0 | D20: 8 | E20: 8 | F20: 5 | G20: 5: JLCPCB freight/duty is inside row 1; other shipping is a lump (one-time row below). Roadmap: ~35 % duty, low end of 35-92.5 % [S8]. Biggest swing factor.
B21: Parts subtotal | C21: =SUM(C8:C20) | D21: =SUM(D8:D20) | E21: =SUM(E8:E20) | F21: =SUM(F8:F20)
B22: Scrap + spares allowance, % | C22: 0 | D22: 0.1 | E22: 0.07 | F22: 0.05 | G22: Alibaba sheet row 15 (estimate). At 5 the spares are a one-time row instead.
B23: Scrap + spares allowance, $ | C23: =C21*C22 | D23: =D21*D22 | E23: =E21*E22 | F23: =F21*F22
B24: Paid assembly labour (box build) | C24: 0 | D24: 0 | E24: 0 | F24: 2.5 | G24: You build 5-100 yourself (time not costed, see row below). 1,000: EMS box build (roadmap §3, estimate).
B25: Variable cost per unit | C25: =C21+C23+C24 | D25: =D21+D23+D24 | E25: =E21+E23+E24 | F25: =F21+F23+F24
A27: One-time costs for the batch (whole $ amount)
B28: Other shipping lump (Adafruit $15 + Seeed $12 + Waveshare $20 + AliExpress $10; JLCPCB's is in row 1) | C28: 57 | D28: 0 | E28: 0 | F28: 0 | G28: Shopping List (option C) shipping rows. At 10+ freight is per unit (row 13).
B29: Bench tools and consumables (tape, glue, drill bit, vinyl, IPA, glasses) | C29: 61 | D29: 0 | E29: 0 | F29: 0 | G29: Shopping List supplies section (charger qty 0 = you own one).
B30: Tester spares (option C: 1 spare of each current + generic camera, screen, battery; 1 magnet piece) | C30: 46.93 | D30: 0 | E30: 0 | F30: 0 | G30: 12.99 + 7 + 6.99 + 4.50 + 5.95 + 3 + 6.50 (Shopping List qty 6 of each kind).
B31: Supplier samples (2 each from 2 suppliers, incl. 4 knockoff shells) + express | C31: 0 | D31: 150 | E31: 150 | F31: 120 | G31: Alibaba sheet row 16 (estimate); KNOCKOFF_SHELL_PLAN.md §1.
B32: Pogo test jig + fixtures | C32: 0 | D32: 0 | E32: 100 | F32: 150 | G32: Roadmap §5: $50-150 (estimate).
B33: Third-party pre-shipment inspection | C33: 0 | D33: 0 | E33: 0 | F33: 300 | G33: ~1 man-day (estimate). Only worth it at 1,000.
B34: One-time total for the batch | C34: =SUM(C28:C33) | D34: =SUM(D28:D33) | E34: =SUM(E28:E33) | F34: =SUM(F28:F33)
B35: One-time per unit | C35: =C34/C$5 | D35: =D34/D$5 | E35: =E34/E$5 | F35: =F34/F$5
B37: COST PER UNIT (before selling-legally costs) | C37: =C25+C35 | D37: =D25+D35 | E37: =E25+E35 | F37: =F25+F35 | G37: Compare: Alibaba_Bulk_Sourcing.xlsx ≈ $92 @10, $46 @100, $34 @1,000 (see 'Checks').
B38: Selling legally? (1 = yes, spread the one-time certification over this batch) | C38: 0 | D38: 0 | E38: 1 | F38: 1 | G38: 5 = testers (not sold); 10 = free / at-cost beta (KNOCKOFF_SHELL_PLAN.md §5). Public sales start at 100.
B39: Certification, lawyer, LLC, trademark, insurance per unit | C39: =C38*'Inputs'!$B$60/C$5 | D39: =D38*'Inputs'!$B$60/D$5 | E39: =E38*'Inputs'!$B$60/E$5 | F39: =F38*'Inputs'!$B$60/F$5
B40: COST PER UNIT incl. selling-legally costs | C40: =C37+C39 | D40: =D37+D39 | E40: =E37+E39 | F40: =F37+F39
B41: Cash for the whole batch (incl. one-time) | C41: =C40*C$5 | D41: =D40*D$5 | E41: =E40*E$5 | F41: =F40*F$5
A43: Information only (not added above)
B44: JLCPCB assembly fee inside the PCBA price: (setup + extended fees) ÷ batch + joints × rate | C44: =('Inputs'!$B$35+'Inputs'!$B$36*'Inputs'!$B$37)/C$5+'Inputs'!$B$38*'Inputs'!$B$39 | D44: =('Inputs'!$B$35+'Inputs'!$B$36*'Inputs'!$B$37)/D$5+'Inputs'!$B$38*'Inputs'!$B$39 | E44: =('Inputs'!$B$35+'Inputs'!$B$36*'Inputs'!$B$37)/E$5+'Inputs'!$B$38*'Inputs'!$B$39 | F44: =('Inputs'!$B$35+'Inputs'!$B$36*'Inputs'!$B$37)/F$5+'Inputs'!$B$38*'Inputs'!$B$39 | G44: Why the board price drops from 10 to 100: the fixed $67 per order is shared. The joint fee itself is only ~$0.40 a board; the rest of row 1 is parts.
...

Sheet API cost
A1: Claude API cost per solve and per subscriber per month
A2: Chosen model and usage come from 'Inputs'. Batch pricing does not apply to live solves.
A4: Item | B4: Value | C4: How it's worked out
A5: Model | B5: ='Inputs'!$B$20 | C5: Inputs
A6: Input price $/M tokens | B6: =INDEX('Inputs'!$B$56:$B$58,MATCH(B5,'Inputs'!$A$56:$A$58,0)) | C6: Model table on Inputs
A7: Output price $/M tokens | B7: =INDEX('Inputs'!$C$56:$C$58,MATCH(B5,'Inputs'!$A$56:$A$58,0)) | C7: Model table
A8: Cache read price $/M tokens | B8: =INDEX('Inputs'!$D$56:$D$58,MATCH(B5,'Inputs'!$A$56:$A$58,0)) | C8: Model table
A9: Output tokens per solve (incl. thinking) | B9: =INDEX('Inputs'!$E$56:$E$58,MATCH(B5,'Inputs'!$A$56:$A$58,0)) | C9: Model table
A10: Input tokens read from cache | B10: ='Inputs'!$B$24*'Inputs'!$B$25 | C10: cached prefix × hit rate
A11: Input tokens written to cache (misses) | B11: ='Inputs'!$B$24*(1-'Inputs'!$B$25) | C11: cached prefix × miss rate
A12: Input tokens at full price | B12: ='Inputs'!$B$23-B10 | C12: all input − cache reads (writes are billed at full price plus the write premium)
A13: Input cost per solve | B13: =(B12*B6+B10*B8+B11*B6*('Inputs'!$B$26-1))/1000000 | C13: full-price input + cache reads + write premium
A14: Output cost per solve | B14: =B9*B7/1000000 | C14: output tokens × output price
A15: COST PER SOLVE | B15: =(B13+B14)*(1-'Inputs'!$B$27) | C15: after any batch discount
A16: Solves per user per month (typical) | B16: ='Inputs'!$B$21*'Inputs'!$B$22 | C16: solves/day × days
A17: API COST PER SUBSCRIBER PER MONTH (typical) | B17: =B15*B16
A18: API cost per month for a user at the fair-use cap | B18: =B15*'Inputs'!$B$9 | C18: cap = 500 solves (proxy)
A19: Solves per month that $15 can pay for | B19: =('Inputs'!$B$7-('Inputs'!$B$7*'Inputs'!$B$10+'Inputs'!$B$11))/B15 | C19: ($15 − card fee) ÷ cost per solve. Hosting excluded.
A20: …as solves per day | B20: =B19/'Inputs'!$B$22
A21: Cap that keeps a heavy user at break-even (suggested MONTHLY_CAP) | B21: =ROUNDDOWN(B19,-1) | C21: rounded down to 10
A28: Scenarios: API cost per user per month (same cache assumptions)
A29: Model | B29: Cost per solve | C29: Light 2/day | D29: Typical (Inputs) | E29: Heavy 10/day | F29: At the cap | G29: Light / heavy solves per day: | H29: 2 | I29: 10
A30: ='Inputs'!$A$56 | B30: =(('Inputs'!$B$23-'Inputs'!$B$24*'Inputs'!$B$25)*'Inputs'!$B$56+'Inputs'!$B$24*'Inputs'!$B$25*'Inputs'!$D$56+'Inputs'!$B$24*(1-'Inputs'!$B$25)*'Inputs'!$B$56*('Inputs'!$B$26-1)+'Inputs'!$E$56*'Inputs'!$C$56)/1000000*(1-'Inputs'!$B$27) | C30: =B30*$H$29*'Inputs'!$B$22 | D30: =B30*'Inputs'!$B$21*'Inputs'!$B$22 | E30: =B30*$I$29*'Inputs'!$B$22 | F30: =B30*'Inputs'!$B$9
A31: ='Inputs'!$A$57 | B31: =(('Inputs'!$B$23-'Inputs'!$B$24*'Inputs'!$B$25)*'Inputs'!$B$57+'Inputs'!$B$24*'Inputs'!$B$25*'Inputs'!$D$57+'Inputs'!$B$24*(1-'Inputs'!$B$25)*'Inputs'!$B$57*('Inputs'!$B$26-1)+'Inputs'!$E$57*'Inputs'!$C$57)/1000000*(1-'Inputs'!$B$27) | C31: =B31*$H$29*'Inputs'!$B$22 | D31: =B31*'Inputs'!$B$21*'Inputs'!$B$22 | E31: =B31*$I$29*'Inputs'!$B$22 | F31: =B31*'Inputs'!$B$9
A32: ='Inputs'!$A$58 | B32: =(('Inputs'!$B$23-'Inputs'!$B$24*'Inputs'!$B$25)*'Inputs'!$B$58+'Inputs'!$B$24*'Inputs'!$B$25*'Inputs'!$D$58+'Inputs'!$B$24*(1-'Inputs'!$B$25)*'Inputs'!$B$58*('Inputs'!$B$26-1)+'Inputs'!$E$58*'Inputs'!$C$58)/1000000*(1-'Inputs'!$B$27) | C32: =B32*$H$29*'Inputs'!$B$22 | D32: =B32*'Inputs'!$B$21*'Inputs'!$B$22 | E32: =B32*$I$29*'Inputs'!$B$22 | F32: =B32*'Inputs'!$B$9
A34: Column C is narrow-looking because it also holds the notes above; numbers are $ per user per month.

Sheet Margins & payback
A1: Margin on the $225 calculator, margin on the $15 subscription, break-even and payback
A2: Columns = batch size. Unit cost includes the selling-legally costs where 'Selling legally' = 1 on 'Unit cost'.
A4: Item | B4: 5 testers | C4: 10 units | D4: 100 units | E4: 1,000 units | F4: How it's worked out
A5: Batch size | B5: ='Unit cost'!C$5 | C5: ='Unit cost'!D$5 | D5: ='Unit cost'!E$5 | E5: ='Unit cost'!F$5
A6: HARDWARE
A7: Price | B7: ='Inputs'!$B$6 | C7: ='Inputs'!$B$6 | D7: ='Inputs'!$B$6 | E7: ='Inputs'!$B$6 | F7: Inputs
A8: Card fee | B8: ='Inputs'!$B$6*'Inputs'!$B$10+'Inputs'!$B$11 | C8: ='Inputs'!$B$6*'Inputs'!$B$10+'Inputs'!$B$11 | D8: ='Inputs'!$B$6*'Inputs'!$B$10+'Inputs'!$B$11 | E8: ='Inputs'!$B$6*'Inputs'!$B$10+'Inputs'!$B$11 | F8: 2.9 % + 30¢
A9: Shipping to the customer | B9: ='Inputs'!$B$12 | C9: ='Inputs'!$B$12 | D9: ='Inputs'!$B$12 | E9: ='Inputs'!$B$12 | F9: Inputs
A10: Returns / warranty allowance | B10: ='Inputs'!$B$6*'Inputs'!$B$13 | C10: ='Inputs'!$B$6*'Inputs'!$B$13 | D10: ='Inputs'!$B$6*'Inputs'!$B$13 | E10: ='Inputs'!$B$6*'Inputs'!$B$13 | F10: % of price
A11: API cost of the free first month | B11: ='API cost'!$B$17*'Inputs'!$B$8 | C11: ='API cost'!$B$17*'Inputs'!$B$8 | D11: ='API cost'!$B$17*'Inputs'!$B$8 | E11: ='API cost'!$B$17*'Inputs'!$B$8 | F11: Every buyer gets it, paying or not
A12: Unit cost (incl. selling-legally costs) | B12: ='Unit cost'!$C$40 | C12: ='Unit cost'!$D$40 | D12: ='Unit cost'!$E$40 | E12: ='Unit cost'!$F$40 | F12: 'Unit cost' sheet
A13: HARDWARE PROFIT PER UNIT | B13: =B7-B8-B9-B10-B11-B12 | C13: =C7-C8-C9-C10-C11-C12 | D13: =D7-D8-D9-D10-D11-D12 | E13: =E7-E8-E9-E10-E11-E12 | F13: price − everything above
A14: Hardware margin % | B14: =B13/B7 | C14: =C13/C7 | D14: =D13/D7 | E14: =E13/E7 | F14: profit ÷ price
A15: SUBSCRIPTION (per paying user per month)
A16: Price | B16: ='Inputs'!$B$7 | C16: ='Inputs'!$B$7 | D16: ='Inputs'!$B$7 | E16: ='Inputs'!$B$7 | F16: Inputs
A17: Card fee | B17: ='Inputs'!$B$7*'Inputs'!$B$10+'Inputs'!$B$11 | C17: ='Inputs'!$B$7*'Inputs'!$B$10+'Inputs'!$B$11 | D17: ='Inputs'!$B$7*'Inputs'!$B$10+'Inputs'!$B$11 | E17: ='Inputs'!$B$7*'Inputs'!$B$10+'Inputs'!$B$11 | F17: the 30¢ hurts most on small charges
A18: Claude API (typical user) | B18: ='API cost'!$B$17 | C18: ='API cost'!$B$17 | D18: ='API cost'!$B$17 | E18: ='API cost'!$B$17 | F18: 'API cost' sheet
A19: Hosting share | B19: ='Inputs'!$B$18/MAX(1,B5*'Inputs'!$B$15) | C19: ='Inputs'!$B$18/MAX(1,C5*'Inputs'!$B$15) | D19: ='Inputs'!$B$18/MAX(1,D5*'Inputs'!$B$15) | E19: ='Inputs'!$B$18/MAX(1,E5*'Inputs'!$B$15) | F19: server $/month ÷ paying users (batch × attach rate)
A20: SUBSCRIPTION PROFIT PER USER PER MONTH | B20: =B16-B17-B18-B19 | C20: =C16-C17-C18-C19 | D20: =D16-D17-D18-D19 | E20: =E16-E17-E18-E19
A21: Subscription margin % | B21: =B20/B16 | C21: =C20/C16 | D21: =D20/D16 | E21: =E20/E16
A22: Same, for a user at the 500-solve cap | B22: =B16-B17-'API cost'!$B$18-B19 | C22: =C16-C17-'API cost'!$B$18-C19 | D22: =D16-D17-'API cost'!$B$18-D19 | E22: =E16-E17-'API cost'!$B$18-E19 | F22: negative = that user costs you money
A23: Does $15 cover the API? (typical user) | B23: =IF(B18<B16-B17,"YES","NO") | C23: =IF(C18<C16-C17,"YES","NO") | D23: =IF(D18<D16-D17,"YES","NO") | E23: =IF(E18<E16-E17,"YES","NO")
A24: LIFETIME (per calculator sold)
A25: Expected paid months in the horizon | B25: ='Inputs'!$B$15*(1-(1-'Inputs'!$B$16)^('Inputs'!$B$17-'Inputs'!$B$8))/'Inputs'!$B$16 | C25: ='Inputs'!$B$15*(1-(1-'Inputs'!$B$16)^('Inputs'!$B$17-'Inputs'!$B$8))/'Inputs'!$B$16 | D25: ='Inputs'!$B$15*(1-(1-'Inputs'!$B$16)^('Inputs'!$B$17-'Inputs'!$B$8))/'Inputs'!$B$16 | E25: ='Inputs'!$B$15*(1-(1-'Inputs'!$B$16)^('Inputs'!$B$17-'Inputs'!$B$8))/'Inputs'!$B$16 | F25: attach × (1 − (1−churn)^(months−free)) ÷ churn
A26: Subscription profit over the horizon | B26: =B25*B20 | C26: =C25*C20 | D26: =D25*D20 | E26: =E25*E20
A27: TOTAL PROFIT PER CALCULATOR (hardware + subscription) | B27: =B13+B26 | C27: =C13+C26 | D27: =D13+D26 | E27: =E13+E26
A28: BREAK-EVEN AND PAYBACK
A29: One-time costs this batch carries (samples, jig, QC, certification) | B29: ='Unit cost'!C34+'Unit cost'!C38*'Inputs'!$B$60 | C29: ='Unit cost'!D34+'Unit cost'!D38*'Inputs'!$B$60 | D29: ='Unit cost'!E34+'Unit cost'!E38*'Inputs'!$B$60 | E29: ='Unit cost'!F34+'Unit cost'!F38*'Inputs'!$B$60 | F29: 'Unit cost' one-time + certification if selling
A30: Variable cost per unit | B30: ='Unit cost'!C25 | C30: ='Unit cost'!D25 | D30: ='Unit cost'!E25 | E30: ='Unit cost'!F25
A31: Profit per unit before one-time costs | B31: =B7-B8-B9-B10-B11-B30 | C31: =C7-C8-C9-C10-C11-C30 | D31: =D7-D8-D9-D10-D11-D30 | E31: =E7-E8-E9-E10-E11-E30
A32: Units to sell to cover the one-time costs (hardware only) | B32: =IF(B31>0,ROUNDUP(B29/B31,0),"never") | C32: =IF(C31>0,ROUNDUP(C29/C31,0),"never") | D32: =IF(D31>0,ROUNDUP(D29/D31,0),"never") | E32: =IF(E31>0,ROUNDUP(E29/E31,0),"never") | F32: one-time ÷ profit per unit
A33: Months for one paying user to repay the free month's API | B33: =IF(B20>0,B11/B20,"never") | C33: =IF(C20>0,C11/C20,"never") | D33: =IF(D20>0,D11/D20,"never") | E33: =IF(E20>0,E11/E20,"never") | F33: free-month API ÷ subscription profit
A34: Months of subscription that would repay the unit cost alone | B34: =IF(B20>0,B12/B20,"never") | C34: =IF(C20>0,C12/C20,"never") | D34: =IF(D20>0,D12/D20,"never") | E34: =IF(E20>0,E12/E20,"never") | F34: if the calculator were sold at cost
A35: Calculators to sell to get the $2,000 budget back | B35: =IF(B13>0,ROUNDUP('Inputs'!$B$50/B13,0),"never") | C35: =IF(C13>0,ROUNDUP('Inputs'!$B$50/C13,0),"never") | D35: =IF(D13>0,ROUNDUP('Inputs'!$B$50/D13,0),"never") | E35: =IF(E13>0,ROUNDUP('Inputs'!$B$50/E13,0),"never") | F35: $2,000 ÷ hardware profit per unit

Sheet Versions
A1: Four versions at 10 / 100 / 1,000: e-paper or LCD, 150 mAh or 1,200-1,500 mAh battery
A2: Starts from the e-paper cost on 'Unit cost' and adds only the differences (each difference also carries that column's scrap %). LCD = v15-LCD board (hardware/stage15_lcd.md): 1.9" 170×320 IPS ST7789 30-pin panel instead of the 2.13" e-paper. Big battery = Adafruit #258 1,200 mAh at 10, Alibaba 504060 ~1,500 mAh at 100+ (enclosure/final_assembly/battery_upgrade.md): needs the custom shell pocket (70 × 41 × 5.4 mm) or a knockoff with room (KNOCKOFF_SHELL_PLAN.md K-D7/K-S5).
A4: # | B4: Item | C4: 10 units | D4: 100 units | E4: 1,000 units | F4: Source / notes
A5: Inputs that differ by version
B6: E-paper panel (from 'Unit cost') | C6: ='Unit cost'!D11 | D6: ='Unit cost'!E11 | E6: ='Unit cost'!F11 | F6: Unit cost row 4.
B7: LCD panel price at 10: BuyDisplay ER-TFT019-1 (no touch, datasheet-verified) | C7: 6.22 | F7: Given 2026-10-08 (verification/14, LCD_PANEL_OPTIONS.md): ~$6-7 each, $6.22 @10, $5.71 @100.
B8: BuyDisplay shipping per order | C8: 12 | F8: Estimate, not quoted: check at checkout and replace.
B9: LCD panel price at 100 / 1,000 (Alibaba / panel maker) | D9: 2.5 | E9: 2.3 | F9: hardware/production/lcd_suppliers.json (2026-10-08): Alibaba, Zhengzhou Zhongjingyuan (ZJY) ST7789V3 30-pin, $2.50 @100, $2.30 @1,000, MOQ 2 (prices from search snippets; confirm drawing + pin table and get a written quote). Sample: Shenzhen Goldenmorning T190X7-C30-01 $1.85-2.50. No listing gave a short-tail FPC price.
B10: LCD panel per unit | C10: =C7+C8/'Unit cost'!D$5 | D10: =D9 | E10: =E9 | F10: 10: BuyDisplay price + one shipping charge shared by the batch. 100/1,000: the line above (Alibaba after a sample check).
B11: v15 PCBA parts change per board (added − removed) | C11: ='Inputs'!$B$45-'Inputs'!$B$44 | D11: ='Inputs'!$B$45-'Inputs'!$B$44 | E11: ='Inputs'!$B$45-'Inputs'!$B$44 | F11: Inputs: v15-LCD board change.
B12: v15 extended-part fee change per board | C12: ='Inputs'!$B$46*'Inputs'!$B$36/'Unit cost'!D$5 | D12: ='Inputs'!$B$46*'Inputs'!$B$36/'Unit cost'!E$5 | E12: ='Inputs'!$B$46*'Inputs'!$B$36/'Unit cost'!F$5 | F12: types change × $3 per order ÷ batch.
B13: 150 mAh battery + its DG surcharge (from 'Unit cost') | C13: ='Unit cost'!D12+'Unit cost'!D13 | D13: ='Unit cost'!E12+'Unit cost'!E13 | E13: ='Unit cost'!F12+'Unit cost'!F13 | F13: Unit cost rows 5-6.
B14: 1,200-1,500 mAh battery | C14: 9.95 | D14: 4 | E14: 3 | F14: 10: Adafruit #258 1,200 mAh $9.95 (battery_upgrade.md). 100/1,000: Alibaba 504060 ~1,500 mAh ~$3-5 at MOQ (estimate). Must come with UN38.3 in the seller's name.
B15: Its dangerous-goods freight surcharge | C15: 0 | D15: 1.2 | E15: 0.5 | F15: Estimate: ~5.5 Wh cell, heavier than the 150 mAh one (UN3481). At 10 it ships ground from Adafruit (in the price).
B16: Longer JST-PH lead / extension (the pocket is under the keypad, ~150 mm lead) | C16: 0.5 | D16: 0.25 | E16: 0.15 | F16: Estimate. Also R2 20 k → 4.7 k on the board for a ~3 h charge (one resistor, no cost change).
A18: Differences per unit (incl. scrap %)
B19: LCD instead of e-paper | C19: =(C10-C6+C11+C12)*(1+'Unit cost'!D22) | D19: =(D10-D6+D11+D12)*(1+'Unit cost'!E22) | E19: =(E10-E6+E11+E12)*(1+'Unit cost'!F22) | F19: (panel − e-paper + board change) × (1 + scrap %).
B20: Big battery instead of 150 mAh | C20: =(C14+C15+C16-C13)*(1+'Unit cost'!D22) | D20: =(D14+D15+D16-D13)*(1+'Unit cost'!E22) | E20: =(E14+E15+E16-E13)*(1+'Unit cost'!F22) | F20: (big cell + its DG + lead − small cell − its DG) × (1 + scrap %).
A22: Results by version
B23: Version | C23: 10 units | D23: 100 units | E23: 1,000 units
B24: Cost per unit before selling-legally costs
B25: E-paper, 150 mAh (= 'Unit cost') | C25: ='Unit cost'!$D$37 | D25: ='Unit cost'!$E$37 | E25: ='Unit cost'!$F$37
B26: LCD, 150 mAh (v15-LCD) | C26: ='Unit cost'!$D$37+C19 | D26: ='Unit cost'!$E$37+D19 | E26: ='Unit cost'!$F$37+E19
B27: E-paper, 1,200-1,500 mAh | C27: ='Unit cost'!$D$37+C20 | D27: ='Unit cost'!$E$37+D20 | E27: ='Unit cost'!$F$37+E20
B28: LCD, 1,200-1,500 mAh (the long-term target) | C28: ='Unit cost'!$D$37+C19+C20 | D28: ='Unit cost'!$E$37+D19+D20 | E28: ='Unit cost'!$F$37+E19+E20
B29: Cost per unit incl. selling-legally costs (FCC, lawyer, LLC, trademark, insurance)
B30: E-paper, 150 mAh (= 'Unit cost') | C30: ='Unit cost'!$D$40 | D30: ='Unit cost'!$E$40 | E30: ='Unit cost'!$F$40
B31: LCD, 150 mAh (v15-LCD) | C31: ='Unit cost'!$D$40+C19 | D31: ='Unit cost'!$E$40+D19 | E31: ='Unit cost'!$F$40+E19
B32: E-paper, 1,200-1,500 mAh | C32: ='Unit cost'!$D$40+C20 | D32: ='Unit cost'!$E$40+D20 | E32: ='Unit cost'!$F$40+E20
B33: LCD, 1,200-1,500 mAh (the long-term target) | C33: ='Unit cost'!$D$40+C19+C20 | D33: ='Unit cost'!$E$40+D19+D20 | E33: ='Unit cost'!$F$40+E19+E20
B34: Hardware profit per $225 unit (same fees, shipping, warranty, free-month API as 'Margins & payback')
B35: E-paper, 150 mAh (= 'Unit cost') | C35: ='Margins & payback'!C7-'Margins & payback'!C8-'Margins & payback'!C9-'Margins & payback'!C10-'Margins & payback'!C11-C30 | D35: ='Margins & payback'!D7-'Margins & payback'!D8-'Margins & payback'!D9-'Margins & payback'!D10-'Margins & payback'!D11-D30 | E35: ='Margins & payback'!E7-'Margins & payback'!E8-'Margins & payback'!E9-'Margins & payback'!E10-'Margins & payback'!E11-E30
B36: LCD, 150 mAh (v15-LCD) | C36: ='Margins & payback'!C7-'Margins & payback'!C8-'Margins & payback'!C9-'Margins & payback'!C10-'Margins & payback'!C11-C31 | D36: ='Margins & payback'!D7-'Margins & payback'!D8-'Margins & payback'!D9-'Margins & payback'!D10-'Margins & payback'!D11-D31 | E36: ='Margins & payback'!E7-'Margins & payback'!E8-'Margins & payback'!E9-'Margins & payback'!E10-'Margins & payback'!E11-E31
B37: E-paper, 1,200-1,500 mAh | C37: ='Margins & payback'!C7-'Margins & payback'!C8-'Margins & payback'!C9-'Margins & payback'!C10-'Margins & payback'!C11-C32 | D37: ='Margins & payback'!D7-'Margins & payback'!D8-'Margins & payback'!D9-'Margins & payback'!D10-'Margins & payback'!D11-D32 | E37: ='Margins & payback'!E7-'Margins & payback'!E8-'Margins & payback'!E9-'Margins & payback'!E10-'Margins & payback'!E11-E32
B38: LCD, 1,200-1,500 mAh (the long-term target) | C38: ='Margins & payback'!C7-'Margins & payback'!C8-'Margins & payback'!C9-'Margins & payback'!C10-'Margins & payback'!C11-C33 | D38: ='Margins & payback'!D7-'Margins & payback'!D8-'Margins & payback'!D9-'Margins & payback'!D10-'Margins & payback'!D11-D33 | E38: ='Margins & payback'!E7-'Margins & payback'!E8-'Margins & payback'!E9-'Margins & payback'!E10-'Margins & payback'!E11-E33
B39: Variable cost per unit (no one-time costs), for the cash budget
B40: E-paper, 150 mAh (= 'Unit cost') | C40: ='Unit cost'!D25 | D40: ='Unit cost'!E25 | E40: ='Unit cost'!F25
B41: LCD, 150 mAh (v15-LCD) | C41: ='Unit cost'!D25+C19 | D41: ='Unit cost'!E25+D19 | E41: ='Unit cost'!F25+E19
A43: Battery life (stage15_lcd.md §3): LCD screen-on ≈ 80-90 mA → ~1.5 h on 150 mAh (charge every 1-2 days), 13-17 h on 1,200-1,500 mAh. The e-paper draws almost nothing between refreshes (~3 h screen-on, weekly charging). That is why the big cell matters for the LCD version.

Sheet Cash budget
A1: Where the $2,000 goes (supply budget), in order
A2: Cash actually leaving your account, in the order of the 2026-10-08 plan. The 2 Casio shells you own are not cash. v14 JLCPCB was ordered 10/8; v15-LCD is verified ORDER (review 14) and is next; nothing else is bought yet.
A4: # | B4: What | C4: When | D4: Amount | E4: Source / notes
A5: 1 | B5: v14 JLCPCB order: 5 PCBs, 5 assembled, delivered (DHL + ~35 % duty) [2026-10-11: NOT ORDERED - v14 was never ordered] | C5: Paid 10/8 | D5: 275 | E5: Shopping List rows 1-2: ≈ $220 for 2 assembled + ≈ $55 for 5 assembled (ranges $200-240 and $50-60). Replace with the real total.
A6: 2 | B6: 5 testers: 3 Casio shells, cameras, screens, batteries, magnet pieces, cables, shipping, supplies (option C) | C6: Now, before boards land | D6: 388.97 | E6: AI_Calculator_Shopping_List.xlsx option C total $663.97 minus the JLCPCB order. Option B would be ≈ $92 less, option A ≈ $2 less.
A7: 3 | B7: v15-LCD prototype panels: 3 × BuyDisplay ER-TFT019-1 (no touch) + shipping | C7: Now, with the v15 order | D7: 32.25 | E7: Shopping List sheet 'v15-LCD prototype' rows 1-2: 3 × ~$6.75 + ~$12 shipping (estimate). Bench checks at arrival: diode test, tail length, backlight current, 3.3 V.
A8: 4 | B8: v15-LCD JLCPCB order (verified ORDER, review 14): 5 PCBs, 5 assembled, delivered | C8: Now | D8: ='Inputs'!$B$47 | E8: Inputs: v15 order estimate. Files hardware/fab_v15_lcd/, steps hardware/ORDER_WALKTHROUGH_v15_lcd.md.
A9: 5 | B9: Knockoff shell samples: 4 clones, 2 sellers (KNOCKOFF_SHELL_PLAN.md §1) | C9: During tester feedback | D9: 60 | E9: Alibaba pair $40-60 incl. DHL + AliExpress/Amazon pair $10-16 (estimate).
A10: 6 | B10: Other supplier samples for bulk (camera, bare LCD panels, 150 mAh + 1,200-1,500 mAh cells, magnet pair + cable) | C10: After shells pass | D10: 90 | E10: Alibaba sheet row 16 total $150 minus the shells (estimate).
A11: 7 | B11: v15-LCD pilot in knockoff shells: the remaining boards + all parts, freight, scrap | C11: After the v15 boards pass the bench checks | D11: ='Inputs'!$B$52*'Versions'!$C$41-MIN('Inputs'!$B$52,'Inputs'!$B$48)*'Unit cost'!$D$8 | E11: Pilot size (Inputs) × LCD variable cost at 10 ('Versions'), minus the boards re-used from the v15 order × the $18 board cost at 10 ('Unit cost' row 1). Includes $8/unit freight and duty.
A12: 8 | B12: Proxy hosting, first 3 months | C12: At beta | D12: =3*'Inputs'!$B$18 | E12: Inputs: server $/month × 3.
A13: 9 | B13: Claude API for the testers' and pilot users' free month | C13: At beta | D13: =('Inputs'!$B$51+'Inputs'!$B$52)*'API cost'!$B$17 | E13: (testers + pilot) × 1 month at the typical rate of the model chosen on Inputs.
A14: 10 | B14: Lawyer / IP clinic: trade-dress check before any unit leaves the house | C14: Before testers go out | D14: 150 | E14: KNOCKOFF_SHELL_PLAN.md §5. University clinic / SCORE can be $0; private $200-500.
A15: 11 | B15: Indiana LLC | C15: Before taking money | D15: ='Inputs'!$B$31 | E15: Inputs (roadmap §4).
A16: 12 | B16: Domain + email for the link page | C16: Before beta | D16: 20 | E16: Estimate.
B17: Subtotal | D17: =SUM(D5:D16)
B18: Contingency, % of subtotal (re-orders, a dead camera, express shipping) | C18: 0.1 | D18: =D17*C18
B19: TOTAL PLANNED SPEND | D19: =D17+D18
B20: Budget | D20: ='Inputs'!$B$50
B21: LEFT OVER (negative = over budget) | D21: ='Inputs'!$B$50-D19
A23: Not inside the $2,000: what the first 100 public units need
B24: 100-unit batch (LCD version): variable cost × 100 + its one-time costs (samples, jig) | D24: =('Unit cost'!E25+'Versions'!D19)*'Unit cost'!E5+'Unit cost'!E34
B25: Selling legally: FCC SDoC, lawyer, LLC, trademark, insurance | D25: ='Inputs'!$B$60
B26: Cash needed before the first public sale | D26: =D24+D25
B27: Pre-orders at $225 (after card fees) that fund it | D27: =ROUNDUP((D26-MAX(0,D21))/('Inputs'!$B$6*(1-'Inputs'!$B$10)-'Inputs'!$B$11),0) | E27: Uses any money left from the $2,000 first. Roadmap §6: take pre-orders before each step up.

Sheet Checks
A1: Cross-checks against earlier files
A3: Check | B3: This model | C3: Earlier figure | D3: Difference | E3: Earlier source
A4: 5 testers: cash for the batch minus the 2 owned shells' value | B4: ='Unit cost'!$C$41-2*'Unit cost'!C9 | C4: 663.97 | D4: =B4-C4 | E4: AI_Calculator_Shopping_List.xlsx option C total ($663.97)
A5: LCD version cost per unit at 100 (before selling-legally) | B5: ='Versions'!$D$26 | C5: 42.22 | D5: =B5-C5 | E5: Alibaba_Bulk_Sourcing.xlsx 'v15-LCD cost by batch' total @100
A6: Cost per unit at 10 (before selling-legally) | B6: ='Unit cost'!$D$37 | C6: 92 | D6: =B6-C6 | E6: Alibaba_Bulk_Sourcing.xlsx 'Cost by batch' (≈ $92)
A7: Cost per unit at 100 (before selling-legally) | B7: ='Unit cost'!$E$37 | C7: 46 | D7: =B7-C7 | E7: Alibaba_Bulk_Sourcing.xlsx (≈ $46)
A8: Cost per unit at 1,000 (before selling-legally) | B8: ='Unit cost'!$F$37 | C8: 34 | D8: =B8-C8 | E8: Alibaba_Bulk_Sourcing.xlsx (≈ $34)
A9: Opus 5.5 cost per solve, no caching (roadmap §3.3) | B9: =(('Inputs'!$B$23)*4+2100*20)/1000000 | C9: 0.052 | D9: =B9-C9 | E9: LAUNCH_ROADMAP.md §3.3 (~$0.052)
A10: Certification etc. one-time | B10: ='Inputs'!$B$60 | C10: 3500 | D10: =B10-C10 | E10: LAUNCH_ROADMAP.md §3 ('about $3.5k')
A12: Differences come from the tester-only rows, rounding in the earlier sheet, and the cache saving on the system prompt.
