Workbook

Sheet Budget
A1: What the 2026-10-08 plan costs now, against the $2,000 budget
A2: All black cells are formulas from the other two sheets. The rest of the $2,000 plan (knockoff samples, pilot, legal) is in hardware/production/COST_MODEL.xlsx 'Cash budget'.
A4: Item | B4: Amount | C4: Notes
A5: Option A, all current parts: 5 testers | B5: ='Testers v14 (5 units)'!$J$48 | C5: Plan ≈ $670.
A6: Option B, all generic screen / camera / battery: 5 testers | B6: ='Testers v14 (5 units)'!$K$48 | C6: Plan ≈ $575. Cheapest, but every unit carries the untested generic parts.
A7: Option C, units 1–3 current, 4–5 generic: 5 testers (recommended) | B7: ='Testers v14 (5 units)'!$L$48 | C7: Plan ≈ $670.
A8: Chosen option | B8: ='Testers v14 (5 units)'!$C$5 | C8: Switch on the 'Testers v14 (5 units)' sheet.
A9: Chosen option total | B9: ='Testers v14 (5 units)'!$N$48
A10: …of which the JLCPCB v14 order (paid 10/8) [2026-10-11: NOT ORDERED - v14 was never ordered] | B10: ='Testers v14 (5 units)'!$N$49
A11: …still to buy for the testers | B11: ='Testers v14 (5 units)'!$N$50
A12: v15-LCD: 3 × BuyDisplay ER-TFT019-1 + the v15 JLCPCB order | B12: ='v15-LCD prototype'!$H$13 | C12: v15 verified ORDER (review 14). Panels ≈ $32, board order ≈ $270 (estimate).
A13: SPEND NOW (testers + v15 order + panels) | B13: =B9+B12
A14: Budget | B14: 2000 | C14: Business plan: $2,000 total budget.
A15: LEFT after these, for the rest of the plan | B15: =B14-B13 | C15: Covers knockoff samples, pilot, server, legal: see COST_MODEL.xlsx 'Cash budget'.
A16: Share of the budget spent now | B16: =B13/B14

Sheet Testers v14 (5 units)
A1: AI Calculator: 5 v14 e-paper TESTERS in genuine Casio fx-115ES shells. Options A / B / C side by side; the switch picks one.
A2: Updated 2026-10-08. Blue = inputs/estimates you can edit (yellow cells); black = formulas. v14 is ordered at JLCPCB (git tag v14-order). Prices: Adafruit/Seeed/Waveshare checked 2026-10-03/06; generic prices are AliExpress-level estimates; JLCPCB delivered ranges from hardware/FAB_VENDOR_COMPARISON.md. [2026-10-11: NOT ORDERED - v14 was never ordered]
A4: Inputs
A5: Option chosen (A / B / C) | C5: C | D5: A = all current parts (Seeed camera, Waveshare screen, Adafruit battery). B = all generic. C = units 1–3 current, 4–5 generic (recommended: known-good parts first, generic ones tested on 2 units).
A6: Tester units to build | C6: 5 | D6: Plan 2026-10-08: 5 testers.
A7: JLCPCB boards assembled (PCBA qty, 2 or 5) | C7: 5 | D7: Nirav was choosing 2 vs 5 at checkout on 10/8. Assumed 5; set 2 if you picked 2 (then only 2 testers can be built until more boards come).
A8: JLCPCB delivered, 5 PCBs with 2 assembled [2026-10-11: NOT ORDERED - v14 was never ordered] | C8: 220 | D8: ≈ $200–240 incl. DHL and ~35 % US duty collected at checkout (DDP); midpoint. Replace with the real order total.
A9: Extra delivered cost for 5 assembled instead of 2 | C9: 55 | D9: ≈ $50–60 more (parts + assembly for 3 more boards, incl. ~35 % duty). Midpoint.
A10: Casio fx-115ES shells you already own | C10: 2 | D10: You own 2 (one is the measured one).
A11: Casio fx-115ES price each | C11: 20 | D11: Walmart $19.99 (LAUNCH_ROADMAP.md [S6]); tax not included. Must be the SAME edition you measured.
A12: Spares per part kind (camera, screen, battery, magnet piece) | C12: 1 | D12: 6 of each for 5 units = 1 spare. In option C each kind (current and generic) gets its own spare.
F14: Option → | G14: A | H14: B | I14: C
A15: Units built with CURRENT parts (Seeed camera, Waveshare screen, Adafruit battery) | G15: =$C$6 | H15: 0 | I15: 3
A16: Units built with GENERIC parts (GDEY0213B74, generic OV5640 AF, 302030 cell) | G16: =$C$6-G15 | H16: =$C$6-H15 | I16: =$C$6-I15
A18: # | B18: Item | C18: Vendor | D18: Link | E18: Part / SKU | F18: Unit $ | G18: Qty A | H18: Qty B | I18: Qty C | J18: Total A | K18: Total B | L18: Total C | M18: Qty (chosen) | N18: Total (chosen) | O18: Order by | P18: Why / notes
B19: JLCPCB board order (v14, ordered 2026-10-08) [2026-10-11: NOT ORDERED - v14 was never ordered]
A20: 1 | B20: JLCPCB v14: 5 PCBs, 2 assembled, DELIVERED (incl. DHL + US duty) [2026-10-11: NOT ORDERED - v14 was never ordered] | C20: JLCPCB | D20: https://jlcpcb.com | E20: ai_calc_pcb_14.zip / tag v14-order | F20: =$C$8 | G20: =1 | H20: =1 | I20: =1 | J20: =$F20*G20 | K20: =$F20*H20 | L20: =$F20*I20 | M20: =IF($C$5="A",G20,IF($C$5="B",H20,I20)) | N20: =$F20*M20 | O20: Ordered 10/8 | P20: 2-layer, 0.8 mm, ENIG, Standard PCBA. Delivered ≈ $200–240 (duty ~35 % collected at checkout, de-minimis suspended). Boards ≈ 10/18–22.
A21: 2 | B21: JLCPCB: boards 3–5 assembled too (per extra board) | C21: JLCPCB | D21: https://jlcpcb.com | E21: PCBA qty 5 | F21: =$C$9/3 | G21: =MAX(0,$C$7-2) | H21: =MAX(0,$C$7-2) | I21: =MAX(0,$C$7-2) | J21: =$F21*G21 | K21: =$F21*H21 | L21: =$F21*I21 | M21: =IF($C$5="A",G21,IF($C$5="B",H21,I21)) | N21: =$F21*M21 | O21: Ordered 10/8 | P21: ≈ $50–60 more for all 3, incl. duty. Qty follows the PCBA input (5 assembled → 3 extra).
B22: Shells
A23: 3 | B23: Casio fx-115ES donor calculator (buy the missing ones) | C23: Walmart / Target / Staples | D23: https://www.walmart.com/ip/418401755 | E23: fx-115ES PLUS (same edition) | F23: =$C$11 | G23: =MAX(0,$C$6-$C$10) | H23: =MAX(0,$C$6-$C$10) | I23: =MAX(0,$C$6-$C$10) | J23: =$F23*G23 | K23: =$F23*H23 | L23: =$F23*I23 | M23: =IF($C$5="A",G23,IF($C$5="B",H23,I23)) | N23: =$F23*M23 | O23: Before boards land | P23: You own 2, buy 3. Check the box shows the same edition you measured (PLUS vs PLUS 2nd edition): posts and ribs can differ.
B24: Per-unit parts: CURRENT (known-good) vs GENERIC (cheaper, needs checking)
A25: 4 | B25: Camera OV5640 AF for XIAO ESP32S3 Sense (CURRENT) | C25: Seeed / DigiKey | D25: https://www.seeedstudio.com/catalogsearch/result/?q=OV5640%20XIAO | E25: 114993115 | F25: 12.99 | G25: =G$15+IF(G$15>0,$C$12,0) | H25: =H$15+IF(H$15>0,$C$12,0) | I25: =I$15+IF(I$15>0,$C$12,0) | J25: =$F25*G25 | K25: =$F25*H25 | L25: =$F25*I25 | M25: =IF($C$5="A",G25,IF($C$5="B",H25,I25)) | N25: =$F25*M25 | O25: Now | P25: J1 (reversed) was worked out for THIS ribbon. Seeed $12.99; DigiKey US $11.99 was faster on 10/6. Avoid the $46 Newegg reseller.
A26: 5 | B26: Camera OV5640 AF, generic 24-pin 0.5 mm DVP (GENERIC) | C26: AliExpress | D26: https://www.aliexpress.us/w/wholesale-ov5640-af-24pin.html | E26: OV5640 AF 24-pin | F26: 7 | G26: =G$16+IF(G$16>0,$C$12,0) | H26: =H$16+IF(H$16>0,$C$12,0) | I26: =I$16+IF(I$16>0,$C$12,0) | J26: =$F26*G26 | K26: =$F26*H26 | L26: =$F26*I26 | M26: =IF($C$5="A",G26,IF($C$5="B",H26,I26)) | N26: =$F26*M26 | O26: Now | P26: ≈ $7 (estimate; listings $4.58–8). BEFORE plugging in: beep test E6, fingers 2 and 15 must beep to GND, and the ribbon length/contact side must match the Seeed one. Wrong pinout = no image (no damage).
A27: 6 | B27: Waveshare 2.13" e-Paper raw panel V4, B/W, SSD1680 (CURRENT) | C27: Waveshare / Amazon Prime | D27: https://www.waveshare.com/2.13inch-e-Paper.htm | E27: SKU 12672 | F27: 6.99 | G27: =G$15+IF(G$15>0,$C$12,0) | H27: =H$15+IF(H$15>0,$C$12,0) | I27: =I$15+IF(I$15>0,$C$12,0) | J27: =$F27*G27 | K27: =$F27*H27 | L27: =$F27*I27 | M27: =IF($C$5="A",G27,IF($C$5="B",H27,I27)) | N27: =$F27*M27 | O27: Now | P27: $6.31–6.99. You also own 1 in your HAT: lower the qty by 1 if you will use it.
A28: 7 | B28: Good Display GDEY0213B74 2.13" e-paper (GENERIC) | C28: AliExpress / Good Display | D28: https://www.good-display.com/product/391.html | E28: GDEY0213B74 | F28: 4.5 | G28: =G$16+IF(G$16>0,$C$12,0) | H28: =H$16+IF(H$16>0,$C$12,0) | I28: =I$16+IF(I$16>0,$C$12,0) | J28: =$F28*G28 | K28: =$F28*H28 | L28: =$F28*I28 | M28: =IF($C$5="A",G28,IF($C$5="B",H28,I28)) | N28: =$F28*M28 | O28: Now | P28: ≈ $4.50 (estimate). Same 250 × 122 SSD1680 family, 24-pin 0.5 mm FPC, same pin order as the V4: compare one with the Waveshare panel before relying on it.
A29: 8 | B29: LiPo 3.7 V 150 mAh JST-PH, 26 × 19.75 × 3.8 mm (CURRENT) | C29: Adafruit | D29: https://www.adafruit.com/product/1317 | E29: #1317 | F29: 5.95 | G29: =G$15+IF(G$15>0,$C$12,0) | H29: =H$15+IF(H$15>0,$C$12,0) | I29: =I$15+IF(I$15>0,$C$12,0) | J29: =$F29*G29 | K29: =$F29*H29 | L29: =$F29*I29 | M29: =IF($C$5="A",G29,IF($C$5="B",H29,I29)) | N29: =$F29*M29 | O29: Now | P29: Fits with no grinding. Meter-check polarity before plugging in (red = + on J4 pad 2).
A30: 9 | B30: LiPo 302030 150 mAh with PCM, JST-PH 2.0 (GENERIC) | C30: AliExpress / Amazon | D30: https://www.aliexpress.us/w/wholesale-302030-lipo-jst-ph.html | E30: 302030 | F30: 3 | G30: =G$16+IF(G$16>0,$C$12,0) | H30: =H$16+IF(H$16>0,$C$12,0) | I30: =I$16+IF(I$16>0,$C$12,0) | J30: =$F30*G30 | K30: =$F30*H30 | L30: =$F30*I30 | M30: =IF($C$5="A",G30,IF($C$5="B",H30,I30)) | N30: =$F30*M30 | O30: Now | P30: ≈ $3 (estimate). 30 × 20 × 3 mm fits the 33.5 × 20.7 × 3.8 envelope. Generic JST leads are OFTEN REVERSED: meter it, swap pins if needed. Must have a protection board (PCM). Candidate: Taiwoo TW302030 (140 mAh, 30 × 20 × 3.0, Alibaba): CAD fit-checked 2026-10-10 (v14 + v15), it fits when placed 1 mm LEFT of the #1317 position (left edge ~1.7 mm from the corner post, top edge 0.8 mm from the lip); same tape L. Order: PCM, JST-PH 2.0 red (+) on pin 2, 50–80 mm leads, UN38.3 + MSDS (hardware/enclosure/final_assembly/battery_upgrade.md).
A31: 10 | B31: Magnetic connector, 4-pin right angle, both halves (all options) | C31: Adafruit | D31: https://www.adafruit.com/product/5358 | E31: #5358 | F31: 6.5 | G31: =$C$6+$C$12 | H31: =$C$6+$C$12 | I31: =$C$6+$C$12 | J31: =$F31*G31 | K31: =$F31*H31 | L31: =$F31*I31 | M31: =IF($C$5="A",G31,IF($C$5="B",H31,I31)) | N31: =$F31*M31 | O31: Now | P31: Legs straightened into J3. Meter-check against the cable before gluing. Alternate (2026-10-10, from Nirav): Yiwei MG04254FRA1S1N is the same part as #5358. Not price-checked.
A32: 11 | B32: Magnetic USB charging cable for the 4-pin (all options, 1 per tester) | C32: Adafruit | D32: https://www.adafruit.com/product/5412 | E32: #5412 | F32: 4.95 | G32: =$C$6 | H32: =$C$6 | I32: =$C$6 | J32: =$F32*G32 | K32: =$F32*H32 | L32: =$F32*I32 | M32: =IF($C$5="A",G32,IF($C$5="B",H32,I32)) | N32: =$F32*M32 | O32: Now (low stock) | P32: Charges AND flashes. Stock was ~35 on 10/6: order first. Backup: Jameco / DigiKey. Alternate (2026-10-10, from Nirav): Yiwei MG0425-UB-60-4P = equivalent of #5412; reads GND, D+, D−, V+ from its N end, like #5412. Same J3 order (1 VBUS, 2 D−, 3 D+, 4 GND, N end at pin 1) and the same meter check before gluing. Not price-checked.
B33: Shipping
A34: 12 | B34: Adafruit shipping (UPS 2nd Day), one box | C34: Adafruit | D34: https://www.adafruit.com | E34: — | F34: 15 | G34: =1 | H34: =1 | I34: =1 | J34: =$F34*G34 | K34: =$F34*H34 | L34: =$F34*I34 | M34: =IF($C$5="A",G34,IF($C$5="B",H34,I34)) | N34: =$F34*M34 | O34: Now | P34: Estimate. The v15 panels now come from BuyDisplay (sheet 'v15-LCD prototype'), not in this box.
A35: 13 | B35: Seeed / DigiKey shipping (only if current cameras) | C35: Seeed | D35: https://www.seeedstudio.com | E35: — | F35: 12 | G35: =IF(G$15>0,1,0) | H35: =IF(H$15>0,1,0) | I35: =IF(I$15>0,1,0) | J35: =$F35*G35 | K35: =$F35*H35 | L35: =$F35*I35 | M35: =IF($C$5="A",G35,IF($C$5="B",H35,I35)) | N35: =$F35*M35 | O35: Now | P35: Estimate.
A36: 14 | B36: Waveshare shipping (only if current screens) | C36: Waveshare | D36: https://www.waveshare.com | E36: — | F36: 20 | G36: =IF(G$15>0,1,0) | H36: =IF(H$15>0,1,0) | I36: =IF(I$15>0,1,0) | J36: =$F36*G36 | K36: =$F36*H36 | L36: =$F36*I36 | M36: =IF($C$5="A",G36,IF($C$5="B",H36,I36)) | N36: =$F36*M36 | O36: Now | P36: Estimate; $0 with Amazon Prime.
A37: 15 | B37: AliExpress shipping (only if generic parts) | C37: AliExpress | D37: https://www.aliexpress.us | E37: — | F37: 10 | G37: =IF(G$16>0,1,0) | H37: =IF(H$16>0,1,0) | I37: =IF(I$16>0,1,0) | J37: =$F37*G37 | K37: =$F37*H37 | L37: =$F37*I37 | M37: =IF($C$5="A",G37,IF($C$5="B",H37,I37)) | N37: =$F37*M37 | O37: Now | P37: Estimate (Choice shipping, 7–15 days). Batteries may ship separately.
B38: Supplies and tools (same for every option; ≈ $61)
A39: 16 | B39: Kapton tape (10–20 mm) | C39: Amazon | D39: https://www.amazon.com/s?k=kapton+tape+10mm | E39: — | F39: 9 | G39: 1 | H39: =G39 | I39: =G39 | J39: =$F39*G39 | K39: =$F39*H39 | L39: =$F39*I39 | M39: =IF($C$5="A",G39,IF($C$5="B",H39,I39)) | N39: =$F39*M39 | O39: This week | P39: Insulates the battery, camera and e-paper back. Estimate.
A40: 17 | B40: Thin double-sided tape 0.1 mm (camera, battery) + about 0.15 mm for the e-paper | C40: Amazon | D40: https://www.amazon.com/s?k=thin+double+sided+tape+0.1mm | E40: — | F40: 10 | G40: 1 | H40: =G40 | I40: =G40 | J40: =$F40*G40 | K40: =$F40*H40 | L40: =$F40*I40 | M40: =IF($C$5="A",G40,IF($C$5="B",H40,I40)) | N40: =$F40*M40 | O40: This week | P40: No foam anywhere: only 0.3 mm above the battery and 0.5 mm above the lens. Estimate.
A41: 18 | B41: Plastic glue / 2-part epoxy | C41: Hardware store | D41: — | E41: — | F41: 6 | G41: 1 | H41: =G41 | I41: =G41 | J41: =$F41*G41 | K41: =$F41*H41 | L41: =$F41*I41 | M41: =IF($C$5="A",G41,IF($C$5="B",H41,I41)) | N41: =$F41*M41 | O41: This week | P41: Glues the magnet piece into the top-wall slot. Estimate.
A42: 19 | B42: 7 mm drill bit (9/32" OK) + 2–3 mm pilot bit + deburring tool | C42: Hardware store | D42: — | E42: — | F42: 12 | G42: 1 | H42: =G42 | I42: =G42 | J42: =$F42*G42 | K42: =$F42*H42 | L42: =$F42*I42 | M42: =IF($C$5="A",G42,IF($C$5="B",H42,I42)) | N42: =$F42*M42 | O42: This week | P42: Camera window in the back cover at KiCad (150, 95.1): pilot first, then 7 mm, then deburr. Estimate.
A43: 20 | B43: Matte black vinyl sheet (window mask, 47.75 × 22.90 mm opening) | C43: Amazon | D43: https://www.amazon.com/s?k=matte+black+adhesive+vinyl+sheet | E43: — | F43: 8 | G43: 1 | H43: =G43 | I43: =G43 | J43: =$F43*G43 | K43: =$F43*H43 | L43: =$F43*I43 | M43: =IF($C$5="A",G43,IF($C$5="B",H43,I43)) | N43: =$F43*M43 | O43: This week | P43: Hides the board edge beside the e-paper glass (hardware/enclosure/final_assembly/window_mask.md). Estimate.
...

Sheet v15-LCD prototype
A1: v15-LCD prototype: the v15 JLCPCB order and the panels for it
A2: v15-LCD board verified "ORDER" in hardware/verification/14_v15_final_preorder.md (2026-10-08). Panel: BuyDisplay ER-TFT019-1, no-touch version (datasheet checked pin for pin; hardware/LCD_PANEL_OPTIONS.md). Buy 3 panels and order the v15 board (hardware/ORDER_WALKTHROUGH_v15_lcd.md). Bench checks at arrival: diode test (pin-1 end), backlight V(R23)/15, panel at 3.3 V, colour flags, tail 36.6 ± 0.3 mm, the 3 moved keys. Adafruit #5394 is only an optional fallback now.
A4: # | B4: Item | C4: Vendor | D4: Link | E4: Part / SKU | F4: Unit $ | G4: Qty | H4: Line total | I4: When | J4: Why / notes
A5: 1 | B5: BuyDisplay ER-TFT019-1 1.9" 170×320 IPS, ST7789P3, 30-pin 0.5 mm FPC, NO touch | C5: BuyDisplay (East Rising) | D5: https://www.buydisplay.com/full-viewing-angle-spi-1-9-inch-ips-tft-lcd-display-panel-170x320-st7789 | E5: ER-TFT019-1 | F5: 6.75 | G5: 3 | H5: =F5*G5 | I5: Now, with the v15 order | J5: ~$6–7 each at 1–9 pcs (6.75 = estimate inside that range; confirm at checkout); $6.22 @10, $5.71 @100. Same glass as the board was designed for; pin 1 lands at the J5 silk tick. Do NOT add the ER-CON30HT-1 socket (J5 is on the board).
A6: 2 | B6: BuyDisplay shipping | C6: BuyDisplay | D6: — | E6: — | F6: 12 | G6: 1 | H6: =F6*G6 | I6: Now | J6: Estimate, not quoted: replace with the checkout figure.
A7: 3 | B7: v15-LCD JLCPCB order: 5 PCBs, 5 assembled (Standard PCBA), delivered incl. DHL + ~35 % duty | C7: JLCPCB | D7: https://jlcpcb.com | E7: hardware/fab_v15_lcd/ (21:38 files) | F7: 270 | G7: 1 | H7: =F7*G7 | I7: Now | J7: Estimate ≈ $255–285 (ORDER_WALKTHROUGH_v15_lcd.md §8): v14 was $275; v15 has one fewer extended part type (13 vs 14, ~$3) and a ~$0.19/board cheaper BOM. Replace with the real total.
A8: 4 | B8: Optional fallback: Adafruit 1.9" 320×170 IPS breakout #5394 (same 30-pin glass inside) | C8: Adafruit | D8: https://www.adafruit.com/product/5394 | E8: #5394 | F8: 17.5 | G8: 0 | H8: =F8*G8 | I8: Only if needed | J8: Fallback only (qty 0). $17.50 (1) / $15.75 (10+). The breakout does not fit the calculator: take the panel off it.
A9: 5 | B9: Adafruit shipping (only if the fallback is bought) | C9: Adafruit | D9: — | E9: — | F9: 10 | G9: =IF(G8>0,1,0) | H9: =F9*G9 | I9: Only if needed | J9: Estimate ≈ $10 if ordered on its own.
A10: 6 | B10: Optional bulk check: Alibaba Goldenmorning T190X7-C30-01 sample (plastic frame) | C10: Alibaba (Shenzhen Goldenmorning) | D10: https://www.alibaba.com/product-detail/1-9-Inch-IPS-TFT-LCD_1601731552729.html | E10: T190X7-C30-01 | F10: 2.5 | G10: 0 | H10: =F10*G10 | I10: Later, before bulk | J10: $1.85–2.50, MOQ 1 (search snippets). Ask for the plastic-frame (~1.4 mm) build. ZJY (~$2.30–2.50) is the other bulk candidate. Qty 0 = not now.
A11: 7 | B11: Alibaba express shipping (only if the sample is bought) | C11: Alibaba | D11: — | E11: — | F11: 20 | G11: =IF(G10>0,1,0) | H11: =F11*G11 | I11: Later | J11: $15–30 by express for a few panels (LCD_PANEL_OPTIONS.md).
B13: TOTAL to buy now (3 panels + the v15 order) | H13: =SUM(H5:H11)
B14: …of which the panels (rows 1–2) | H14: =SUM(H5:H6)
B16: Board parts JLCPCB places on the v15 order (inside row 3, info only)
B17: Board part | C17: LCSC | F17: Unit $ (JLCPCB 10/8) | G17: Qty / board | H17: Per board
A18: J5 | B18: HDGC 0.5K-HX-30PWB 30-pin 0.5 mm FPC socket, dual contact (LcdReversed footprint) | C18: C2919501 | F18: 0.36 | G18: 1 | H18: =F18*G18
A19: Q4 | B19: AO3401A P-MOSFET (LCD power switch) | C19: C15127 | F19: 0.1 | G19: 1 | H19: =F19*G19
A20: Q5 | B20: AO3400A N-MOSFET (backlight switch) | C20: C20917 | F20: 0.09 | G20: 1 | H20: =F20*G20
A21: R21, R22, C36 | B21: 100 k ×2, 100 nF | C21: C25741 / C1525 | F21: 0.002 | G21: 3 | H21: =F21*G21
A22: R23 | B22: 15 Ω 0603 (was 22 Ω until review 14; extended part, ~$3 one-off fee) | C22: C22810 | F22: 0.0013 | G22: 1 | H22: =F22*G22
B23: Added parts per v15 board (the 17 removed e-paper parts make the board ≈ $0.19 cheaper overall) | H23: =SUM(H18:H22)
A25: The rest of the $2,000 plan (knockoff samples, pilot, legal) is in hardware/production/COST_MODEL.xlsx 'Cash budget' (rows 3–4 there = this sheet).
