Workbook

Sheet Cost by batch
A1: AI Calculator: bulk cost per unit at 10 / 100 / 1,000 units (knockoff 991ES-style shell)
A2: Prices as of 2026-10-05. Blue = estimate inputs you can edit; black = formulas. Sources: 'Supplier options' and 'Sources' sheets, and Claude outputs/LAUNCH_ROADMAP.md §3 (JLCPCB, freight). Alibaba pages sit behind a CAPTCHA for automated reading, so listing prices come from search-index snippets: confirm every number by RFQ before paying. Battery updated 2026-10-06: Adafruit #1317 150 mAh (26 × 19.75 × 3.8) replaces the #1570 100 mAh.
N3: Batch size → | O3: 10 | P3: 100 | Q3: 1000 | R3: ← edit batch sizes here
A4: # | B4: Category | C4: Item & key spec | D4: Source @10 | E4: Source @100 | F4: Source @1,000 | G4: Main link | H4: Qty / unit | I4: Unit $ @10 | J4: Unit $ @100 | K4: Unit $ @1,000 | L4: Per-unit $ @10 | M4: Per-unit $ @100 | N4: Per-unit $ @1,000 | O4: Batch total @10 | P4: Batch total @100 | Q4: Batch total @1,000 | R4: Price basis / notes
A5: 1 | B5: PCBA | C5: Main board v14: PCB 2-layer 0.8 mm ENIG + Standard PCBA (ESP32-S3-MINI-1, TCA8418, LDOs, FPCs, passives) | D5: JLCPCB | E5: JLCPCB | F5: JLCPCB (Economic/Standard PCBA) | G5: link | H5: 1 | I5: 18 | J5: 9 | K5: 7.3 | L5: =$H5*I5 | M5: =$H5*J5 | N5: =$H5*K5 | O5: =L5*O$3 | P5: =M5*P$3 | Q5: =N5*Q$3 | R5: LAUNCH_ROADMAP.md §3 price-scaling table (JLCPCB + LCSC breaks, estimate). Stays with JLCPCB at all sizes. Extended-part fees ($3 x 14 types) vanish into per-unit cost at 100+.
A6: 2 | B6: Shell | C6: Knockoff 991ES PLUS-style calculator (shell, key mat, window, screws, slide cover); board removed | D6: AliExpress / Amazon (MOQ 1) | E6: Alibaba (MOQ ~20-50) | F6: Alibaba factory (same mould, MOQ 500-3,000) | G6: link | H6: 1 | I6: 6 | J6: 3.99 | K6: 3.25 | L6: =$H6*I6 | M6: =$H6*J6 | N6: =$H6*K6 | O6: =L6*O$3 | P6: =M6*P$3 | Q6: =N6*Q$3 | R6: Alibaba listing seen at $3.25-3.99, MOQ 20 [S1]; factories quote $1.50-3.50 at MOQ 3,000 [S2]. @10 = retail clone incl. shipping (estimate).
A7: 3 | B7: Camera | C7: OV5640 AF, 24-pin 0.5 mm FPC DVP, Seeed XIAO-Sense pinout, AF lens | D7: Seeed SS114993115 (known pinout) | E7: Alibaba OEM (V-Vision etc.) after pinout check | F7: Alibaba OEM, custom FPC length | G7: link | H7: 1 | I7: 12 | J7: 6 | K7: 4.5 | L7: =$H7*I7 | M7: =$H7*J7 | N7: =$H7*K7 | O7: =L7*O$3 | P7: =M7*P$3 | Q7: =N7*Q$3 | R7: Roadmap table [S8]; Alibaba OV5640 24-pin modules ~$5-18 [S3]; eBay/AliExpress AF 24-pin ~GBP 7.49 [S4].
A8: 4 | B8: Display | C8: 2.13" B/W raw e-paper, SSD1680, 250x122, 24-pin 0.5 mm FPC (GDEY0213B74 / Waveshare V4 family) | D8: Waveshare raw panel | E8: Good Display direct (RFQ) | F8: Good Display direct (RFQ) | G8: link | H8: 1 | I8: 6.6 | J8: 5.5 | K8: 4 | L8: =$H8*I8 | M8: =$H8*J8 | N8: =$H8*K8 | O8: =L8*O$3 | P8: =M8*P$3 | Q8: =N8*Q$3 | R8: Waveshare $6.31-6.99 [S8]; GDEY0213B74 retail ~EUR 6.89 [S5]; volume price by RFQ to buyepaper@good-display.com (estimate).
A9: 5 | B9: Battery | C9: LiPo 3.7 V ~150 mAh with PCM, JST-PH 2.0 plug (red = +, Adafruit polarity), Adafruit #1317 class 26 × 19.75 × 3.8 mm; max 33.5 × 20.7 × 3.8 mm incl. PCM fold | D9: Adafruit #1317 | E9: Alibaba stock cell + PH2.0 lead | F9: Alibaba custom cell (~382026 / 402025 class, 150 mAh) with certs | G9: link | H9: 1 | I9: 5.95 | J9: 1.8 | K9: 1.3 | L9: =$H9*I9 | M9: =$H9*J9 | N9: =$H9*K9 | O9: =L9*O$3 | P9: =M9*P$3 | Q9: =N9*Q$3 | R9: Adafruit #1317 $5.95 [S8] (switched from the 100 mAh #1570 on 2026-10-06; same price). Alibaba 401230 listings $0.56-1.60 [S6] are 100 mAh references (401230 is 4.0 x 12 x 30: too thick and wide); ask for a ~150 mAh cell in 26 x 20 x 3.8. @100/@1,000 include PH lead + PCM (estimate). Named bulk candidate (2026-10-10): Taiwoo TW302030, 140 mAh, 30 × 20 × 3.0; fits the fx-115ES spot in CAD when placed 1 mm left of the #1317 position ('Supplier options' row 49); price not yet quoted, so the estimates stand.
A10: 6 | B10: Battery | C10: Dangerous-goods (UN3481) air-freight surcharge for batteries, per unit | D10: (in Adafruit price) | E10: Alibaba supplier DG air / express | F10: Sea or DG air with the cells | H10: 1 | I10: 0 | J10: 0.8 | K10: 0.3 | L10: =$H10*I10 | M10: =$H10*J10 | N10: =$H10*K10 | O10: =L10*O$3 | P10: =M10*P$3 | Q10: =N10*Q$3 | R10: Estimate. Many forwarders refuse loose LiPo; ask the supplier to ship with UN38.3 + MSDS.
A11: 7 | B11: Charging | C11: 4-pin magnetic pogo connector pair, ~2.54 mm pitch, board half fits J3 (VBUS, D-, D+, GND from N end) | D11: Adafruit #5358 | E11: Alibaba RA pogo pair (sample-checked) | F11: Alibaba OEM pair, drawing-approved | G11: link | H11: 1 | I11: 5.85 | J11: 1.8 | K11: 1.2 | L11: =$H11*I11 | M11: =$H11*J11 | N11: =$H11*K11 | O11: =L11*O$3 | P11: =M11*P$3 | Q11: =N11*Q$3 | R11: Adafruit $5.85 @10 [S8]; Alibaba MG04-254-RA $1.80, multiples of 20 [S7]; roadmap $1.20 @1,000 (estimate). Alternate (2026-10-10, from Nirav): Yiwei MG04254FRA1S1N = the same part as Adafruit #5358 (Supplier options row 47); price not checked.
A12: 8 | B12: Charging | C12: Magnetic USB cable for the 4-pin connector (cable N->S: GND, D+, D-, VBUS), in the box | D12: Adafruit #5412 | E12: Alibaba (same supplier as connector) | F12: Alibaba OEM, same supplier as connector | G12: link | H12: 1 | I12: 4.95 | J12: 1.8 | K12: 1.4 | L12: =$H12*I12 | M12: =$H12*J12 | N12: =$H12*K12 | O12: =L12*O$3 | P12: =M12*P$3 | Q12: =N12*Q$3 | R12: Adafruit $4.95 [S8]; roadmap estimate $1.40-1.80 for OEM cable. Alternate (2026-10-10, from Nirav): Yiwei MG0425-UB-60-4P = equivalent of #5412, reads GND, D+, D−, V+ from its N end (Supplier options row 48); price not checked.
A13: 9 | B13: Packaging | C13: Retail box + foam/EVA insert (printed) | D13: Plain mailer box (local / Amazon) | E13: Alibaba custom rigid box, MOQ 100 | F13: Alibaba custom box + die-cut insert | G13: link | H13: 1 | I13: 1.5 | J13: 1 | K13: 0.6 | L13: =$H13*I13 | M13: =$H13*J13 | N13: =$H13*K13 | O13: =L13*O$3 | P13: =M13*P$3 | Q13: =N13*Q$3 | R13: Alibaba rigid boxes w/ foam insert $0.50-1.00 at MOQ 100 [S9]; @10 estimate.
A14: 10 | B14: Packaging | C14: Quick-start card / small manual (with 'not affiliated with Casio', FCC text later) | D14: Home print | E14: Local / online printer | F14: Alibaba printer (MOQ 500) | G14: link | H14: 1 | I14: 0.1 | J14: 0.25 | K14: 0.05 | L14: =$H14*I14 | M14: =$H14*J14 | N14: =$H14*K14 | O14: =L14*O$3 | P14: =M14*P$3 | Q14: =N14*Q$3 | R14: Manual printing $0.03 (500+) to $0.01 (10k+) [S10]; small runs estimate.
A15: 11 | B15: Packaging | C15: Serial / QC label sticker + polybag for calculator | D15: Home print | E15: Online label printer | F15: Alibaba / Uline | G15: link | H15: 1 | I15: 0.15 | J15: 0.1 | K15: 0.05 | L15: =$H15*I15 | M15: =$H15*J15 | N15: =$H15*K15 | O15: =L15*O$3 | P15: =M15*P$3 | Q15: =N15*Q$3 | R15: Estimate.
A16: 12 | B16: Consumables | C16: Kapton tape 10 mm, thin double-sided tape (3M 9448A-type), B-7000/E6000 glue; per unit share | D16: Amazon / AliExpress | E16: AliExpress / LCSC | F16: Alibaba bulk rolls | G16: link | H16: 1 | I16: 0.5 | J16: 0.3 | K16: 0.2 | L16: =$H16*I16 | M16: =$H16*J16 | N16: =$H16*K16 | O16: =L16*O$3 | P16: =M16*P$3 | Q16: =N16*Q$3 | R16: Estimate (a 30 m roll covers roughly 100+ units).
A17: 13 | B17: Freight | C17: Inbound freight + US import duty on China content (PCBA, parts, shells) | D17: DHL (JLCPCB DDP) | E17: DHL / consolidated | F17: Forwarder, sea/air LCL | G17: link | H17: 1 | I17: 8 | J17: 8 | K17: 5 | L17: =$H17*I17 | M17: =$H17*J17 | N17: =$H17*K17 | O17: =L17*O$3 | P17: =M17*P$3 | Q17: =N17*Q$3 | R17: Roadmap table, assumes ~35 % duty (low end of 35-92.5 %) [S8]. Biggest swing factor.
A18: 14 | B18: Labour | C18: Final assembly (strip knockoff, mask, grind, fit board, test) | D18: Nirav | E18: Nirav (+ jig) | F18: EMS box build / local helper | H18: 1 | I18: 0 | J18: 0 | K18: 2.5 | L18: =$H18*I18 | M18: =$H18*J18 | N18: =$H18*K18 | O18: =L18*O$3 | P18: =M18*P$3 | Q18: =N18*Q$3 | R18: Roadmap table (estimate). Your own time is not costed at 10/100.
A19: 15 | B19: Overage | C19: Scrap + spares allowance (% of rows above, excl. labour) — DOA cameras/panels, cracked shells | D19: Allowance %: | I19: 0.1 | J19: 0.07 | K19: 0.05 | L19: =I19*(SUM(L5:L18)-L18) | M19: =J19*(SUM(M5:M18)-M18) | N19: =K19*(SUM(N5:N18)-N18) | O19: =L19*O$3 | P19: =M19*P$3 | Q19: =N19*Q$3 | R19: Estimate. Order this many extra parts, not just budget for them.
A20: 16 | B20: One-time | C20: Samples from each supplier (2 each, from 2 suppliers per part) + express shipping | H20: per batch | I20: 150 | J20: 150 | K20: 120 | L20: =I20/O$3 | M20: =J20/P$3 | N20: =K20/Q$3 | O20: =I20 | P20: =J20 | Q20: =K20 | R20: Estimate. Per-unit = amount / batch size. Repeat a smaller sample round whenever you change supplier.
A21: 17 | B21: One-time | C21: Pre-shipment inspection / golden-sample sign-off (third-party QC, e.g. 1 man-day) | H21: per batch | I21: 0 | J21: 0 | K21: 300 | L21: =I21/O$3 | M21: =J21/P$3 | N21: =K21/Q$3 | O21: =I21 | P21: =J21 | Q21: =K21 | R21: Estimate (~$300 per man-day typical). Only worth it at 1,000.
A22: 18 | B22: One-time | C22: Test jig (pogo bed + spring pins) and fixtures | H22: per batch | I22: 0 | J22: 100 | K22: 150 | L22: =I22/O$3 | M22: =J22/P$3 | N22: =K22/Q$3 | O22: =I22 | P22: =J22 | Q22: =K22 | R22: Roadmap §5 estimate $50-150.
C23: TOTAL | K23: Per-unit / batch → | L23: =SUM(L5:L22) | M23: =SUM(M5:M22) | N23: =SUM(N5:N22) | O23: =SUM(O5:O22) | P23: =SUM(P5:P22) | Q23: =SUM(Q5:Q22)
C24: Check: batch total / batch size (should equal the per-unit total) | L24: =O23/O$3 | M24: =P23/P$3 | N24: =Q23/Q$3
A26: Note: Not included: FCC SDoC, LLC, lawyer, trademark (≈ $3.5k one-time before selling, roadmap §4), Claude API cost, sales-channel fees, your own time.
A27: Note: Bold assumption: the v14 board fits the knockoff shell. It was laid out for the fx-115ES (posts, key pads, ribs). See 'Checks before bulk' row 1.
A28: Note: At 10 units the cheapest path is mostly retail (Adafruit, Seeed, Waveshare, AliExpress). Alibaba starts paying off at 100; custom battery/connector at ~500+.

Sheet v15-LCD cost by batch
A1: AI Calculator v15-LCD: bulk cost per unit at 10 / 100 / 1,000 units (1.9" colour LCD instead of the e-paper; knockoff 991ES-style shell)
A2: Added 2026-10-08, updated 2026-10-08 evening. Same layout as 'Cost by batch'; every row links to it except row 1 (PCBA + v15 change) and row 4 (LCD panel). Blue = inputs. v15 board verified 'ORDER' (hardware/verification/14_v15_final_preorder.md); upload files hardware/fab_v15_lcd/, steps hardware/ORDER_WALKTHROUGH_v15_lcd.md. Panel: BuyDisplay ER-TFT019-1 (datasheet-verified). Bigger battery option below the total.
N3: Batch size → | O3: ='Cost by batch'!O3 | P3: ='Cost by batch'!P3 | Q3: ='Cost by batch'!Q3 | R3: ← batch sizes come from 'Cost by batch'
A4: # | B4: Category | C4: Item & key spec | D4: Source @10 | E4: Source @100 | F4: Source @1,000 | G4: Main link | H4: Qty / unit | I4: Unit $ @10 | J4: Unit $ @100 | K4: Unit $ @1,000 | L4: Per-unit $ @10 | M4: Per-unit $ @100 | N4: Per-unit $ @1,000 | O4: Batch total @10 | P4: Batch total @100 | Q4: Batch total @1,000 | R4: Price basis / notes
A5: 1 | B5: PCBA | C5: Main board v15-LCD: PCB 2-layer 0.8 mm ENIG + Standard PCBA (v14 board minus the e-paper booster, plus J5 30-pin socket, Q4/Q5 LCD power + backlight FETs, R23 15 Ω C22810) | D5: JLCPCB | E5: JLCPCB | F5: JLCPCB (Economic/Standard PCBA) | G5: link | H5: 1 | I5: ='Cost by batch'!I5+$I$35-$I$36+$I$37*$I$38/O$3 | J5: ='Cost by batch'!J5+$I$35-$I$36+$I$37*$I$38/P$3 | K5: ='Cost by batch'!K5+$I$35-$I$36+$I$37*$I$38/Q$3 | L5: =$H5*I5 | M5: =$H5*J5 | N5: =$H5*K5 | O5: =L5*O$3 | P5: =M5*P$3 | Q5: =N5*Q$3 | R5: 'Cost by batch' PCBA price + (parts added − removed) + extended-type change × $3 ÷ batch. Files: hardware/fab_v15_lcd/ (21:38). Verified ORDER (review 14), not yet ordered.
A6: 2 | B6: Shell | C6: Knockoff 991ES PLUS-style calculator (shell, key mat, window, screws, slide cover); board removed | D6: AliExpress / Amazon (MOQ 1) | E6: Alibaba (MOQ ~20-50) | F6: Alibaba factory (same mould, MOQ 500-3,000) | G6: link | H6: ='Cost by batch'!H6 | I6: ='Cost by batch'!I6 | J6: ='Cost by batch'!J6 | K6: ='Cost by batch'!K6 | L6: =$H6*I6 | M6: =$H6*J6 | N6: =$H6*K6 | O6: =L6*O$3 | P6: =M6*P$3 | Q6: =N6*Q$3 | R6: Alibaba listing seen at $3.25-3.99, MOQ 20 [S1]; factories quote $1.50-3.50 at MOQ 3,000 [S2]. @10 = retail clone incl. shipping (estimate).
A7: 3 | B7: Camera | C7: OV5640 AF, 24-pin 0.5 mm FPC DVP, Seeed XIAO-Sense pinout, AF lens | D7: Seeed SS114993115 (known pinout) | E7: Alibaba OEM (V-Vision etc.) after pinout check | F7: Alibaba OEM, custom FPC length | G7: link | H7: ='Cost by batch'!H7 | I7: ='Cost by batch'!I7 | J7: ='Cost by batch'!J7 | K7: ='Cost by batch'!K7 | L7: =$H7*I7 | M7: =$H7*J7 | N7: =$H7*K7 | O7: =L7*O$3 | P7: =M7*P$3 | Q7: =N7*Q$3 | R7: Roadmap table [S8]; Alibaba OV5640 24-pin modules ~$5-18 [S3]; eBay/AliExpress AF 24-pin ~GBP 7.49 [S4].
A8: 4 | B8: Display | C8: 1.9" 170×320 IPS LCD, ST7789, 30-pin 0.5 mm FPC (36.6 mm tail), 4 white LEDs; TFT1901 / N190-1732TBWPG01 family (LilyGO T-Display-S3 panel) | D8: BuyDisplay ER-TFT019-1, no touch (datasheet-verified pin for pin) | E8: Alibaba Goldenmorning T190X7-C30-01 / ZJY, after a sample check | F8: Alibaba / panel maker; optional short-tail FPC (Goldenmorning, TSD, NoseDisplay, BuyDisplay custom FPC) | G8: link | H8: 1 | I8: =$I$31+$I$32/O$3 | J8: =$I$33 | K8: =$I$34 | L8: =$H8*I8 | M8: =$H8*J8 | N8: =$H8*K8 | O8: =L8*O$3 | P8: =M8*P$3 | Q8: =N8*Q$3 | R8: @10: BuyDisplay ER-TFT019-1 $6.22 each @10 ($5.71 @100) + one shipping charge shared by the batch (estimate). @100/@1,000: Alibaba ZJY (Zhengzhou Zhongjingyuan) ST7789V3 30-pin $2.50 @100 / $2.30 @1,000, MOQ 2, or Goldenmorning T190X7-C30-01 (plastic frame) (hardware/production/lcd_suppliers.json; search-snippet prices, confirm by quote and a sample check) [S15]. Adafruit #5394 ($17.50) is only an optional fallback now.
A9: 5 | B9: Battery | C9: LiPo 3.7 V ~150 mAh with PCM, JST-PH 2.0 plug (red = +, Adafruit polarity), Adafruit #1317 class 26 × 19.75 × 3.8 mm; max 33.5 × 20.7 × 3.8 mm incl. PCM fold | D9: Adafruit #1317 | E9: Alibaba stock cell + PH2.0 lead | F9: Alibaba custom cell (~382026 / 402025 class, 150 mAh) with certs | G9: link | H9: ='Cost by batch'!H9 | I9: ='Cost by batch'!I9 | J9: ='Cost by batch'!J9 | K9: ='Cost by batch'!K9 | L9: =$H9*I9 | M9: =$H9*J9 | N9: =$H9*K9 | O9: =L9*O$3 | P9: =M9*P$3 | Q9: =N9*Q$3 | R9: Adafruit #1317 $5.95 [S8] (switched from the 100 mAh #1570 on 2026-10-06; same price). Alibaba 401230 listings $0.56-1.60 [S6] are 100 mAh references (401230 is 4.0 x 12 x 30: too thick and wide); ask for a ~150 mAh cell in 26 x 20 x 3.8. @100/@1,000 include PH lead + PCM (estimate).
A10: 6 | B10: Battery | C10: Dangerous-goods (UN3481) air-freight surcharge for batteries, per unit | D10: (in Adafruit price) | E10: Alibaba supplier DG air / express | F10: Sea or DG air with the cells | H10: ='Cost by batch'!H10 | I10: ='Cost by batch'!I10 | J10: ='Cost by batch'!J10 | K10: ='Cost by batch'!K10 | L10: =$H10*I10 | M10: =$H10*J10 | N10: =$H10*K10 | O10: =L10*O$3 | P10: =M10*P$3 | Q10: =N10*Q$3 | R10: Estimate. Many forwarders refuse loose LiPo; ask the supplier to ship with UN38.3 + MSDS.
A11: 7 | B11: Charging | C11: 4-pin magnetic pogo connector pair, ~2.54 mm pitch, board half fits J3 (VBUS, D-, D+, GND from N end) | D11: Adafruit #5358 | E11: Alibaba RA pogo pair (sample-checked) | F11: Alibaba OEM pair, drawing-approved | G11: link | H11: ='Cost by batch'!H11 | I11: ='Cost by batch'!I11 | J11: ='Cost by batch'!J11 | K11: ='Cost by batch'!K11 | L11: =$H11*I11 | M11: =$H11*J11 | N11: =$H11*K11 | O11: =L11*O$3 | P11: =M11*P$3 | Q11: =N11*Q$3 | R11: Adafruit $5.85 @10 [S8]; Alibaba MG04-254-RA $1.80, multiples of 20 [S7]; roadmap $1.20 @1,000 (estimate). Alternate (2026-10-10, from Nirav): Yiwei MG04254FRA1S1N = the same part as Adafruit #5358 (Supplier options row 47); price not checked.
A12: 8 | B12: Charging | C12: Magnetic USB cable for the 4-pin connector (cable N->S: GND, D+, D-, VBUS), in the box | D12: Adafruit #5412 | E12: Alibaba (same supplier as connector) | F12: Alibaba OEM, same supplier as connector | G12: link | H12: ='Cost by batch'!H12 | I12: ='Cost by batch'!I12 | J12: ='Cost by batch'!J12 | K12: ='Cost by batch'!K12 | L12: =$H12*I12 | M12: =$H12*J12 | N12: =$H12*K12 | O12: =L12*O$3 | P12: =M12*P$3 | Q12: =N12*Q$3 | R12: Adafruit $4.95 [S8]; roadmap estimate $1.40-1.80 for OEM cable. Alternate (2026-10-10, from Nirav): Yiwei MG0425-UB-60-4P = equivalent of #5412, reads GND, D+, D−, V+ from its N end (Supplier options row 48); price not checked.
A13: 9 | B13: Packaging | C13: Retail box + foam/EVA insert (printed) | D13: Plain mailer box (local / Amazon) | E13: Alibaba custom rigid box, MOQ 100 | F13: Alibaba custom box + die-cut insert | G13: link | H13: ='Cost by batch'!H13 | I13: ='Cost by batch'!I13 | J13: ='Cost by batch'!J13 | K13: ='Cost by batch'!K13 | L13: =$H13*I13 | M13: =$H13*J13 | N13: =$H13*K13 | O13: =L13*O$3 | P13: =M13*P$3 | Q13: =N13*Q$3 | R13: Alibaba rigid boxes w/ foam insert $0.50-1.00 at MOQ 100 [S9]; @10 estimate.
A14: 10 | B14: Packaging | C14: Quick-start card / small manual (with 'not affiliated with Casio', FCC text later) | D14: Home print | E14: Local / online printer | F14: Alibaba printer (MOQ 500) | G14: link | H14: ='Cost by batch'!H14 | I14: ='Cost by batch'!I14 | J14: ='Cost by batch'!J14 | K14: ='Cost by batch'!K14 | L14: =$H14*I14 | M14: =$H14*J14 | N14: =$H14*K14 | O14: =L14*O$3 | P14: =M14*P$3 | Q14: =N14*Q$3 | R14: Manual printing $0.03 (500+) to $0.01 (10k+) [S10]; small runs estimate.
A15: 11 | B15: Packaging | C15: Serial / QC label sticker + polybag for calculator | D15: Home print | E15: Online label printer | F15: Alibaba / Uline | G15: link | H15: ='Cost by batch'!H15 | I15: ='Cost by batch'!I15 | J15: ='Cost by batch'!J15 | K15: ='Cost by batch'!K15 | L15: =$H15*I15 | M15: =$H15*J15 | N15: =$H15*K15 | O15: =L15*O$3 | P15: =M15*P$3 | Q15: =N15*Q$3 | R15: Estimate.
A16: 12 | B16: Consumables | C16: Kapton tape 10 mm, thin double-sided tape (3M 9448A-type), B-7000/E6000 glue; per unit share | D16: Amazon / AliExpress | E16: AliExpress / LCSC | F16: Alibaba bulk rolls | G16: link | H16: ='Cost by batch'!H16 | I16: ='Cost by batch'!I16 | J16: ='Cost by batch'!J16 | K16: ='Cost by batch'!K16 | L16: =$H16*I16 | M16: =$H16*J16 | N16: =$H16*K16 | O16: =L16*O$3 | P16: =M16*P$3 | Q16: =N16*Q$3 | R16: Estimate (a 30 m roll covers roughly 100+ units).
A17: 13 | B17: Freight | C17: Inbound freight + US import duty on China content (PCBA, parts, shells) | D17: DHL (JLCPCB DDP) | E17: DHL / consolidated | F17: Forwarder, sea/air LCL | G17: link | H17: ='Cost by batch'!H17 | I17: ='Cost by batch'!I17 | J17: ='Cost by batch'!J17 | K17: ='Cost by batch'!K17 | L17: =$H17*I17 | M17: =$H17*J17 | N17: =$H17*K17 | O17: =L17*O$3 | P17: =M17*P$3 | Q17: =N17*Q$3 | R17: Roadmap table, assumes ~35 % duty (low end of 35-92.5 %) [S8]. Biggest swing factor.
A18: 14 | B18: Labour | C18: Final assembly (strip knockoff, mask, grind, fit board, test) | D18: Nirav | E18: Nirav (+ jig) | F18: EMS box build / local helper | H18: ='Cost by batch'!H18 | I18: ='Cost by batch'!I18 | J18: ='Cost by batch'!J18 | K18: ='Cost by batch'!K18 | L18: =$H18*I18 | M18: =$H18*J18 | N18: =$H18*K18 | O18: =L18*O$3 | P18: =M18*P$3 | Q18: =N18*Q$3 | R18: Roadmap table (estimate). Your own time is not costed at 10/100.
A19: 15 | B19: Overage | C19: Scrap + spares allowance (% of rows above, excl. labour) — DOA cameras/panels, cracked shells | D19: Allowance %: | I19: ='Cost by batch'!I19 | J19: ='Cost by batch'!J19 | K19: ='Cost by batch'!K19 | L19: =I19*(SUM(L5:L18)-L18) | M19: =J19*(SUM(M5:M18)-M18) | N19: =K19*(SUM(N5:N18)-N18) | O19: =L19*O$3 | P19: =M19*P$3 | Q19: =N19*Q$3 | R19: Estimate. Order this many extra parts, not just budget for them.
A20: 16 | B20: One-time | C20: Samples from each supplier (2 each, from 2 suppliers per part) + express shipping | H20: per batch | I20: ='Cost by batch'!I20 | J20: ='Cost by batch'!J20 | K20: ='Cost by batch'!K20 | L20: =I20/O$3 | M20: =J20/P$3 | N20: =K20/Q$3 | O20: =I20 | P20: =J20 | Q20: =K20 | R20: Estimate. Per-unit = amount / batch size. Repeat a smaller sample round whenever you change supplier.
A21: 17 | B21: One-time | C21: Pre-shipment inspection / golden-sample sign-off (third-party QC, e.g. 1 man-day) | H21: per batch | I21: ='Cost by batch'!I21 | J21: ='Cost by batch'!J21 | K21: ='Cost by batch'!K21 | L21: =I21/O$3 | M21: =J21/P$3 | N21: =K21/Q$3 | O21: =I21 | P21: =J21 | Q21: =K21 | R21: Estimate (~$300 per man-day typical). Only worth it at 1,000.
A22: 18 | B22: One-time | C22: Test jig (pogo bed + spring pins) and fixtures | H22: per batch | I22: ='Cost by batch'!I22 | J22: ='Cost by batch'!J22 | K22: ='Cost by batch'!K22 | L22: =I22/O$3 | M22: =J22/P$3 | N22: =K22/Q$3 | O22: =I22 | P22: =J22 | Q22: =K22 | R22: Roadmap §5 estimate $50-150.
C23: TOTAL | K23: Per-unit / batch → | L23: =SUM(L5:L22) | M23: =SUM(M5:M22) | N23: =SUM(N5:N22) | O23: =SUM(O5:O22) | P23: =SUM(P5:P22) | Q23: =SUM(Q5:Q22)
C24: Check: batch total / batch size (should equal the per-unit total) | L24: =O23/O$3 | M24: =P23/P$3 | N24: =Q23/Q$3
A26: Note: LCD vs e-paper: the panel itself is ~$6.22 at 10 (BuyDisplay) and ~$2.30-2.50 at 100+ (Alibaba) instead of $4-6.60, and the board loses 17 booster parts and gains 7. But the LCD draws ~80-90 mA with the screen on: ~1.5 h screen-on on the 150 mAh cell (stage15_lcd.md §3), so the long-term pairing is the 1,200-1,500 mAh cell below.
A27: Note: Not included (as on 'Cost by batch'): FCC SDoC, LLC, lawyer, trademark (≈ $3.5k one-time), Claude API, sales fees. Full model: hardware/production/COST_MODEL.xlsx 'Versions'.
A30: Inputs for the LCD version
C31: LCD panel @10: BuyDisplay ER-TFT019-1 (no touch), per panel at the 10-pc price | I31: 6.22 | R31: Given 2026-10-08 (review 14 / LCD_PANEL_OPTIONS.md): ~$6-7 each, $6.22 @10, $5.71 @100. Datasheet rev 2.0 checked pin for pin.
C32: BuyDisplay shipping per order (estimate) | I32: 12 | R32: Estimate, not quoted: check at checkout on buydisplay.com and replace.
C33: LCD panel @100 (Alibaba / panel maker) | I33: 2.5 | R33: Alibaba ZJY (Zhengzhou Zhongjingyuan) ST7789V3 30-pin $2.50 @100 / $2.30 @1,000, MOQ 2 (hardware/production/lcd_suppliers.json, 2026-10-08; search-snippet prices, confirm by quote) [S15].
C34: LCD panel @1,000 (Alibaba / panel maker, maybe short-tail FPC) | I34: 2.3 | R34: Alibaba ZJY (Zhengzhou Zhongjingyuan) ST7789V3 30-pin $2.50 @100 / $2.30 @1,000, MOQ 2 (hardware/production/lcd_suppliers.json, 2026-10-08; search-snippet prices, confirm by quote) [S15]. Ask NoseDisplay / BuyDisplay / QDtech for an 18-20 mm FPC tail.
C35: v15 parts added per board: J5 C2919501 $0.36 + Q4 AO3401A $0.10 + Q5 AO3400A C20917 $0.09 + R21, R22, C36 3 × $0.002 + R23 15 Ω C22810 $0.0013 | I35: 0.5573 | R35: JLCPCB prices 2026-10-08 (stage15_lcd.md §3; R23 changed to 15 Ω C22810 in review 14).
C36: v14 e-paper parts removed per board: J2, L1, Q3, R11, R12, D3-D5, C20-C30 (17 parts) | I36: 0.75 | R36: Estimate from LCSC 1-off prices; stage 15: board ≈ $1 cheaper.
C37: Change in JLCPCB extended part types (L1, Q3, R12 out; J5 C2919501 and R23 C22810 in) | I37: -1 | R37: v14 had 14 extended types, v15 has 13 (review 14 stock list). $3 per type per order.
C38: Extended-part fee per type per order | I38: 3 | R38: JLCPCB rule (roadmap §3.1).
A40: Compare and bigger-battery option (per unit) | L40: @10 | M40: @100 | N40: @1,000
C41: E-paper version, 150 mAh ('Cost by batch' total) | L41: ='Cost by batch'!L23 | M41: ='Cost by batch'!M23 | N41: ='Cost by batch'!N23
C42: LCD version, 150 mAh (this sheet's total) | L42: =L23 | M42: =M23 | N42: =N23
C43: Difference LCD − e-paper | L43: =L42-L41 | M43: =M42-M41 | N43: =N42-N41
C44: 1,200-1,500 mAh cell (@10 Adafruit #258 1,200 mAh; @100+ Alibaba 504060 ~1,500 mAh) | L44: 9.95 | M44: 4 | N44: 3 | R44: Adafruit #258 $9.95 (enclosure/final_assembly/battery_upgrade.md); Alibaba 504060 ~$3-5 at MOQ (estimate). Needs UN38.3 in the seller's name.
...

Sheet Supplier options
A1: Supplier options per component (2-3+ listings each)
A2: As of 2026-10-05. Price/MOQ text is what search indexes showed for each listing; Alibaba prices change daily and many listings hide the supplier name until you log in. 'Supplier' = company where shown, else '(see listing)'. Lead times are typical for the category (estimate) unless noted.
A3: Component | B3: Opt | C3: Platform | D3: Supplier | E3: Listing | F3: Link | G3: MOQ | H3: Price tiers seen | I3: Lead time | J3: Shipping notes | K3: Spec checks to ask the supplier | L3: Use for batch
A4: Shell (knockoff) | B4: 1 | C4: Alibaba | D4: (see listing) | E4: Multifunctional Function Calculator 991ES PLUS Scientific | F4: open listing | G4: Ask (often 20-100) | H4: Ask; category $3.25-3.99 @MOQ 20 seen [S1] | I4: 7-15 days stock; 25-35 days custom | J4: Express ~5-10 days; ~120 g each | K4: Same model + same mould every batch (ask mould/model no.); photos of the INSIDE (PCB removed) and of the key-mat contact side; fx-991ES/115ES key grid (5x? rows, same pitch); screw-post positions with a ruler in shot; board removable without breaking the key mat; no Casio logo/name printed; send 2 samples first. | L4: 100 / 1,000
A5: Shell (knockoff) | B5: 2 | C5: Alibaba | D5: (see listing) | E5: OS-991ES Plus Digital Scientific Calculator, 2-line, 417 functions | F5: open listing | G5: Ask | H5: Ask | I5: 7-15 days | J5: Express or sea for 1,000 | K5: Same model + same mould every batch (ask mould/model no.); photos of the INSIDE (PCB removed) and of the key-mat contact side; fx-991ES/115ES key grid (5x? rows, same pitch); screw-post positions with a ruler in shot; board removable without breaking the key mat; no Casio logo/name printed; send 2 samples first. | L5: 100 / 1,000
A6: Shell (knockoff) | B6: 3 | C6: Alibaba | D6: (see listing) | E6: Wholesale Price Scientific Calculator 991 ES Plus, 417 functions | F6: open listing | G6: Ask | H6: Ask | I6: 7-15 days | J6: - | K6: Same model + same mould every batch (ask mould/model no.); photos of the INSIDE (PCB removed) and of the key-mat contact side; fx-991ES/115ES key grid (5x? rows, same pitch); screw-post positions with a ruler in shot; board removable without breaking the key mat; no Casio logo/name printed; send 2 samples first. | L6: 100 / 1,000
A7: Shell (knockoff) | B7: 4 | C7: Alibaba (factories) | D7: Shantou Eates Electronic; Guangzhou Cania Technology; Truly Instrument (SC-991ES+) | E7: Supplier directory: FX-991-style calculator wholesalers | F7: open listing | G7: 50-3,000 | H7: $1.50-3.50 @3,000; $2.35-4.46 @2; Truly $5-12 @200 [S2] | I7: 15-30 days | J7: Sea for 1,000+ | K7: Same model + same mould every batch (ask mould/model no.); photos of the INSIDE (PCB removed) and of the key-mat contact side; fx-991ES/115ES key grid (5x? rows, same pitch); screw-post positions with a ruler in shot; board removable without breaking the key mat; no Casio logo/name printed; send 2 samples first. Prefer a factory with ITS OWN design (no Casio trade dress) for sales. | L7: 1,000
A8: Shell (knockoff) | B8: 5 | C8: AliExpress / Amazon | D8: Runzon RZ-991ES PLUS and generic '991ES PLUS 240 functions' clones | E8: AliExpress search: 991ES PLUS calculator | F8: open listing | G8: 1 | H8: ~$5-8 incl. shipping (estimate) | I8: AliExpress 7-15 days; Amazon 1-2 days | J8: Buy 2 from 2 sellers to compare moulds | K8: Same model + same mould every batch (ask mould/model no.); photos of the INSIDE (PCB removed) and of the key-mat contact side; fx-991ES/115ES key grid (5x? rows, same pitch); screw-post positions with a ruler in shot; board removable without breaking the key mat; no Casio logo/name printed; send 2 samples first. | L8: 10 (and samples)
A9: Shell (knockoff) | B9: 6 | C9: Made-in-China | D9: (various) | E9: 991ES wholesale search (alternative marketplace) | F9: open listing | G9: Varies | H9: Varies | I9: 15-30 days | J9: - | K9: Same model + same mould every batch (ask mould/model no.); photos of the INSIDE (PCB removed) and of the key-mat contact side; fx-991ES/115ES key grid (5x? rows, same pitch); screw-post positions with a ruler in shot; board removable without breaking the key mat; no Casio logo/name printed; send 2 samples first. | L9: backup
A10: Camera OV5640 AF | B10: 1 | C10: Alibaba | D10: Shenzhen V-Vision Technology Co., Ltd. | E10: Auto Focus OV5640 OEM 24pin/30pin MIPI/DVP module (v-vision5640-AF) | F10: open listing | G10: Ask (OEM; typ. 1-100) | H10: Category $5-18 [S3] | I10: Stock 3-7 days; custom FPC 2-4 weeks | J10: Antistatic packing; express | K10: Pinout drawing of the 24-pin FPC vs the Seeed XIAO-Sense OV5640 (pins 2 and 15 = GND on our J1); FPC length and which side the contacts face; AF motor type + driver (VCM); DOVDD 1.8/2.8 V; lens FOV ~66-70°; heat-sink or not; same module revision for repeat orders. V-Vision does custom FPC length: request the XIAO-Sense pinout. | L10: 100 / 1,000
A11: Camera OV5640 AF | B11: 2 | C11: Alibaba | D11: (see listing) | E11: CMOS Sensor 24pin OV5640 DVP module, AF or FF | F11: open listing | G11: Ask | H11: Ask | I11: Ask | J11: - | K11: Pinout drawing of the 24-pin FPC vs the Seeed XIAO-Sense OV5640 (pins 2 and 15 = GND on our J1); FPC length and which side the contacts face; AF motor type + driver (VCM); DOVDD 1.8/2.8 V; lens FOV ~66-70°; heat-sink or not; same module revision for repeat orders. | L11: 100 / 1,000
A12: Camera OV5640 AF | B12: 3 | C12: AliExpress | D12: (see listing) | E12: OV5640 5MP Auto Focus Camera Module for ESP32-CAM, 24PIN 0.5 mm | F12: open listing | G12: 1 | H12: ~$8-10 (GBP 7.49 / EUR 8.65 similar) [S4] | I12: 7-15 days | J12: Choice/standard shipping | K12: Pinout drawing of the 24-pin FPC vs the Seeed XIAO-Sense OV5640 (pins 2 and 15 = GND on our J1); FPC length and which side the contacts face; AF motor type + driver (VCM); DOVDD 1.8/2.8 V; lens FOV ~66-70°; heat-sink or not; same module revision for repeat orders. | L12: samples / 10
A13: Camera OV5640 AF | B13: 4 | C13: Seeed / distributors | D13: Seeed Studio (SKU 114993115) | E13: OV5640 Camera for XIAO ESP32S3 Sense (reference pinout) | F13: open listing | G13: 1 | H13: ~$14 (roadmap) [S8] | I13: Distributor stock | J13: - | K13: Known-good pinout: use as the golden sample to compare others. | L13: 10
A14: E-paper 2.13" | B14: 1 | C14: Alibaba | D14: Dalian Good Display Co., Ltd. (16+ yrs on Alibaba) | E14: Cheap e-paper 2.13" 250x122 GDEY0213B74 | F14: open listing | G14: 1 (samples) | H14: Ask; retail ~EUR 6.89 [S5] | I14: Stock 3-7 days | J14: Ships from Dalian; trays | K14: Exact part: GDEY0213B74 (or Waveshare 2.13 V4) with SSD1680Z8; 24-pin 0.5 mm FPC, same pin order as the V4; outline 59.2 x 29.2 x 1.0 mm; bare panel (no driver PCB); datasheet + LUT/init code version; tray packaging. | L14: 100 / 1,000
A15: E-paper 2.13" | B15: 2 | C15: Good Display direct | D15: Dalian Good Display (buyepaper@good-display.com) | E15: GDEY0213B74 product page / RFQ | F15: open listing | G15: Ask | H15: RFQ for 100 / 1,000 | I15: 1-3 weeks | J15: DHL/FedEx | K15: Exact part: GDEY0213B74 (or Waveshare 2.13 V4) with SSD1680Z8; 24-pin 0.5 mm FPC, same pin order as the V4; outline 59.2 x 29.2 x 1.0 mm; bare panel (no driver PCB); datasheet + LUT/init code version; tray packaging. | L15: 100 / 1,000
... A46: LCD 1.9" 170x320 (v15) | B46: 6 | C46: Alibaba | D46: Zhengzhou Zhongjingyuan Electronic Technology (ZJY) | E46: 1.9" 170x320 30-pin TFT, ST7789V3 | F46: open listing | G46: 2 | H46: $2.50 @100 / $2.30 @1,000 [S15] | I46: Ask | J46: Express / sea | K46: Recommended BULK. Confirm the drawing and pin table first (pin 7 SCL, 8 RS, 20 LEDA, 21-24 LEDK); ask about an 18-20 mm FPC tail. | L46: 100 / 1,000
A47: Magnetic connector | B47: 5 | C47: Manufacturer | D47: Yiwei | E47: MG04254FRA1S1N: the same part as Adafruit #5358 (4-contact right-angle magnetic piece) | F47: no link yet | G47: Ask | H47: Ask (not price-checked) | I47: Ask | J47: - | K47: Same part as #5358 (Nirav, 2026-10-10). Fits J3 as #5358 does: J3 = 1 VBUS, 2 D-, 3 D+, 4 GND, piece N end at pin 1. Meter check with the real cable before gluing. | L47: 100 / 1,000
A48: Magnetic USB cable | B48: 5 | C48: Manufacturer | D48: Yiwei | E48: MG0425-UB-60-4P magnetic USB cable, 4-pin, 60 cm: equivalent of Adafruit #5412 | F48: no link yet | G48: Ask | H48: Ask (not price-checked) | I48: Ask | J48: - | K48: Reads GND, D+, D-, V+ from its N end, matching #5412 (Nirav, 2026-10-10). Mates with the MG04254FRA1S1N / #5358 piece. Meter check before gluing. | L48: 100 / 1,000
A49: LiPo ~150 mAh | B49: 6 | C49: Alibaba | D49: Taiwoo (TW302030 listing) | E49: Taiwoo TW302030 LiPo 3.7 V 140 mAh, L 30 (+2/−0.5) × W 20 ± 0.5 × T 3.0 ± 0.3 mm incl. PCB; connector 1.0 / 1.25 / 2.0 mm; PCM customised (3.0 V cut-off available) | F49: no link yet | G49: Ask | H49: Ask (not price-checked) | I49: Ask | J49: DG (UN3481); ask for UN38.3 + MSDS | K49: CAD fit-checked 2026-10-10 on v14 and v15 (hardware/enclosure/final_assembly/variant_battery_tw302030/results.json): FITS when placed 1 mm LEFT of the #1317 position (left edge ~1.7 mm from the corner post, top edge 0.8 mm from the lip; a cell over ~20.3 mm wide goes right up to the lip). Ask for: PCM included; JST-PH 2.0 2-pin, red (+) on pin 2, black on pin 1 (photo); leads 50–80 mm leaving the short (lead) end; UN38.3 + MSDS in the seller's name. Meter the polarity of every sample. | L49: 100 / 1,000

Sheet Supplier message templates
A1: Supplier message templates (paste into Alibaba chat / email; replace [brackets])
A2: For | B2: Message
A3: Any supplier: first contact | B3: Hi, I'm developing a small handheld electronics product in the USA. I'd like 2 samples of [item / listing link] first, then possibly [100] and later [1,000] pcs. Please send: (1) price tiers for 10 / 100 / 1,000 / 3,000 pcs, (2) sample price + DHL shipping to [ZIP] USA, (3) lead time for each quantity, (4) datasheet / drawing, (5) whether you can use Trade Assurance. Thank you!
A4: Knockoff calculator (shell) | B4: Hi, I'm interested in your 991ES PLUS scientific calculator [link]. Before ordering 2 samples, please send: (1) photos of the inside with the circuit board removed, (2) a photo of the rubber key-mat contact side, (3) the model number and mould number, and confirmation future orders use the SAME mould, (4) outer size and screw positions, (5) price for 10 / 100 / 1,000 pcs, plain version with NO brand logo printed. Can you supply the shell + key mat + window + screws + slide cover without the PCB and battery?
A5: OV5640 AF camera | B5: Hi, I need an OV5640 autofocus DVP module with a 24-pin 0.5 mm FPC, same pinout as the Seeed 'OV5640 for XIAO ESP32S3 Sense'. Please send the FPC pinout drawing, the FPC length and contact side, lens FOV, and AF driver. Can you make the FPC [xx] mm long? Price for 2 samples, 100 and 1,000 pcs, and lead time please.
A6: E-paper (Good Display) | B6: Hi Good Display team, I'm using the GDEY0213B74 (2.13" B/W, SSD1680, 24-pin FPC) in a handheld product. Please quote 10, 100 and 1,000 pcs of the bare panel, with lead time and DHL shipping to [ZIP] USA. Please also confirm the current datasheet version and that the FPC pin order is unchanged. Is there an MOQ?
A7: LiPo battery | B7: Hi, I need a 3.7 V LiPo, about 150 mAh, about 26 x 20 x 3.8 mm and at most 33.5 x 20.7 x 3.8 mm INCLUDING the protection board, with a JST-PH 2.0 plug, red wire = + (photo please, same polarity as Adafruit #1317), lead length [xx] mm. Please send: UN38.3 test summary, MSDS/SDS, IEC 62133 (CB) report for THIS model in your company name, the cell model (e.g. 382026/402025), price for 2 samples / 100 / 1,000, and how you ship batteries to the USA (UN3481).
A8: Magnetic connector + cable | B8: Hi, I need a 4-pin magnetic pogo connector pair, ~2.54 mm pitch, plus a matching USB-A (or USB-C) magnetic cable, 60 cm. The board half is right-angle (or board-edge SMT). Please send a dimensioned drawing with magnet polarity. Pin order on the cable plug, N to S: GND, D+, D-, VBUS (USB data must work, not only charging). Price for 2 sample sets / 100 / 1,000 and lead time please. Can you customise pin order and cable length?
A9: Packaging | B9: Hi, please quote a printed box with a die-cut foam/EVA insert for a calculator ([L x W x H] mm) plus a USB cable. Quantities 100 and 1,000, 1 colour print outside, and the price of a printed sample. Please send the die-line template, and quote a small folded manual (A6, 8 pages, B/W) too.
A10: Follow-up / negotiation | B10: Thank you for the quote. Samples arrived and passed. For the [100] pcs order: can you match [$x], keep the same materials/revision as the samples, and send photos of the finished goods before shipping? Please confirm in the PI that the product matches the approved sample.
A11: LCD 1.9" panel (v15) | B11: Hi [supplier] team, I'm using a 1.9" 170x320 IPS TFT with an ST7789 controller and a 30-pin 0.5 mm FPC (same as BuyDisplay ER-TFT019-1 / TFT1901 / N190-1732TBWPG01, the LilyGO T-Display-S3 panel) in a handheld product. Please quote 10, 100 and 1,000 pcs, with lead time and DHL shipping to [ZIP] USA. Please send the drawing and datasheet, confirm the controller is ST7789 (not a clone), the pin order (pin 7 SCL, 8 RS, 20 LEDA, 21-24 LEDK), the FPC tail length, and whether you can make the FPC tail 18-20 mm long (MOQ and price). Please quote the plastic-frame (about 1.4 mm thick) build, not the 2.1 mm metal frame. Is there an MOQ?

Sheet Checks before bulk
A1: Checks before any bulk order
A2: # | B2: When | C2: Check | D2: Why | E2: Pass if
A3: 1 | B3: Before ANY board order for the knockoff | C3: Measure the knockoff: PCB outline, screw posts, ribs, key-mat contact positions, window, solar box. Compare to the v14 board. | D3: v14 was laid out for the fx-115ES (posts, key pads, rib grinds). A 991ES clone mould will likely differ. | E3: Paper dry-fit of the v14 outline (hardware/fitcheck) lands on the posts and every key pill sits on a pad; else plan a v15 outline.
A4: 2 | B4: Samples | C4: Buy 2 samples of every part from 2 suppliers each before paying for 100. | D4: Listings change; photos are often generic. | E4: Each sample passes the spec checks on 'Supplier options'.
A5: 3 | B5: Samples | C5: Clone mould consistency: buy the knockoff from 2 DIFFERENT orders (or sellers) and measure both. | D5: Same listing name can ship different moulds batch to batch. | E5: Key grid, posts and outline within ±0.2 mm; same key legends.
A6: 4 | B6: Bulk order | C6: Ask the shell supplier to confirm the mould/model number in the PI and to send photos of the bulk goods before shipping. | D6: Stops a silent mould swap. | E6: PI lists the model + 'same as approved sample'.
A7: 5 | B7: Camera | C7: Beep-test every new camera vendor: FPC fingers 2 and 15 to GND; run the self-test image. | D7: J1 is reversed for one cable direction; generic pinouts vary. | E7: Image OK, AF moves, no heat issue.
A8: 6 | B8: E-paper | C8: Run the full and partial refresh test with the current firmware LUT. | D8: Panel revisions can need different init code. | E8: No ghosting; partial refresh works.
A9: 7 | B9: Battery | C9: Check polarity on J4 with a meter BEFORE plugging in; read the UN38.3 summary model name. | D9: Reversed JST leads are common; reports must cover THIS cell. | E9: Red = + on J4 pad 2 (the "+" silk; pad 1 is GND); report names match label.
A10: 8 | B10: Charging | C10: Mate cable + board connector; check USB enumeration and the ~50 mA charge current. | D10: Pin order N->S must give VBUS, D-, D+, GND at J3. | E10: COM port appears; charging LED/STAT OK.
A11: 9 | B11: Payment | C11: Use Trade Assurance; pay 30 % deposit at most; keep all chat on-platform. | D11: Buyer protection. | E11: -
A12: 10 | B12: Shipping | C12: Batteries ship as UN3481 with SDS; ask your forwarder before booking. | D12: DG refusal / fines. | E12: Forwarder confirms DG lane.
A13: 11 | B13: Legal (before selling at scale) | C13: The knockoff mimics Casio's fx-991ES trade dress. OK for prototypes and free/labelled betas. Before selling at scale: move to the custom shell or a supplier with ITS OWN design, remove any branding/model names that copy Casio, and add 'not affiliated with Casio'. | D13: Trademark / trade-dress risk (roadmap §4). | E13: Lawyer/clinic check done; no Casio-like logo or name on the unit or box.
A14: 12 | B14: Legal | C14: FCC SDoC, UN38.3 paperwork and LLC before selling (roadmap §4). | D14: Required to sell / ship. | E14: Docs on file.
A15: 13 | B15: LCD (v15) | C15: Diode test on the first panels of every batch: LED drop (~2.6 V) between finger 20 and fingers 21-24 (ER-TFT019-1: cathode on 22); check the tail length (36.6 ± 0.3 mm), the frame thickness (plastic ~1.4 mm) and the controller (ST7789). | D15: J5 is numbered for one tail direction (verification/13 S1, confirmed on the ER-TFT019-1 drawing in verification/14); clone controllers need other init code. | E15: LED fingers in the TOP half of J5; colour bars + backlight sweep pass in the self-test.

Sheet Sources
A1: Sources (checked 2026-10-05)
A2: Ref | B2: What | C2: URL
A3: S1 | B3: Alibaba 991ES PLUS clone listing $3.25-3.99, MOQ 20 (Accio market summary) | C3: https://de.accio.com/business/casio-fx-es-991-bestseller
A4: S2 | B4: FX-991 clone wholesalers: Shantou Eates, Guangzhou Cania, Truly; $1.50-3.50 @3,000 | C4: https://electronics.alibaba.com/supplier/scientific-calculator-fx-991-wholesaler
A5: S3 | B5: Alibaba OV5640 AF 24-pin OEM (V-Vision) and category price range | C5: https://www.alibaba.com/product-detail/Auto-Focus-OV5640-camera-OEM-24pin_60812933393.html
A6: S4 | B6: OV5640 AF 24-pin DVP module retail (eBay) GBP 7.49 | C6: https://www.ebay.de/itm/187207860087
A7: S5 | B7: Good Display GDEY0213B74 specs (59.2 x 29.2 x 1.0 mm, 24-pin 0.5 mm, SSD1680Z) | C7: https://www.good-display.com/product/391.html
A8: S6 | B8: Alibaba 401230 100 mAh LiPo listings ($0.56-1.60) | C8: https://www.alibaba.com/showroom/401230-lipo-battery-3.7v-100mah.html
A9: S7 | B9: Alibaba MG04-254-RA 4-pin magnetic pogo $1.80 (multiples of 20); Dongguan pogo price ranges | C9: https://www.alibaba.com/product-detail/Horizontal-4-Pogo-Pin-Magnetic-Electrical_1600423063435.html
A10: S8 | B10: LAUNCH_ROADMAP.md §1, §3 (JLCPCB, Adafruit, Waveshare, Seeed, freight/duty table) | C10: Claude outputs/LAUNCH_ROADMAP.md
A11: S9 | B11: Alibaba gift boxes with foam insert, MOQ 100, $0.20-1.02 | C11: https://www.alibaba.com/showroom/gift-boxes-with-foam-insert.html
A12: S10 | B12: Manual printing $0.03 (500-4,999) / $0.01 (10k+) | C12: https://sourcing.ship4wd.com/product/instruction-manual-custom-printing-factory-typesetting-design-advertising-brochure-custom-printing-employment-contract-employee-handbook
A13: S11 | B13: AliExpress 1.9" 30Pin ST7789 bare panel $2.82 + $5.27 shipping (seen 2026-10-08; hardware/LCD_PANEL_OPTIONS.md row B) | C13: hardware/LCD_PANEL_OPTIONS.md
... A17: S15 | B17: Alibaba LCD search 2026-10-08 (Goldenmorning sample $1.85-2.50; ZJY $2.50 @100 / $2.30 @1,000): hardware/production/lcd_suppliers.json | C17: https://www.alibaba.com/product-detail/1-9-Inch-170x320-30-PIN_1600647344150.html
A18: Note | B18: Alibaba product pages returned a CAPTCHA to automated reading on 2026-10-05; numbers are from search-index snippets and must be confirmed by RFQ.
